[2025-03-28 21:53:10] Exception: A Page Is Not Found 
in /Users/azimsaibou/Desktop/php projects/sous-controle-docker/www/sous_controle/tests/Unit/ExceptionHandlerTest.php 
on line 35
Trace: #0 /Users/azimsaibou/Desktop/php projects/sous-controle-docker/www/sous_controle/vendor/pestphp/pest/src/Factories/TestCaseMethodFactory.php(168): P\Tests\Unit\ExceptionHandlerTest->{closure:/Users/azimsaibou/Desktop/php projects/sous-controle-docker/www/sous_controle/tests/Unit/ExceptionHandlerTest.php:31}()
#1 [internal function]: P\Tests\Unit\ExceptionHandlerTest->{closure:Pest\Factories\TestCaseMethodFactory::getClosure():158}()
#2 /Users/azimsaibou/Desktop/php projects/sous-controle-docker/www/sous_controle/vendor/pestphp/pest/src/Concerns/Testable.php(419): call_user_func_array(Object(Closure), Array)
#3 /Users/azimsaibou/Desktop/php projects/sous-controle-docker/www/sous_controle/vendor/pestphp/pest/src/Support/ExceptionTrace.php(26): P\Tests\Unit\ExceptionHandlerTest->{closure:Pest\Concerns\Testable::__callClosure():419}()
#4 /Users/azimsaibou/Desktop/php projects/sous-controle-docker/www/sous_controle/vendor/pestphp/pest/src/Concerns/Testable.php(419): Pest\Support\ExceptionTrace::ensure(Object(Closure))
#5 /Users/azimsaibou/Desktop/php projects/sous-controle-docker/www/sous_controle/vendor/pestphp/pest/src/Concerns/Testable.php(321): P\Tests\Unit\ExceptionHandlerTest->__callClosure(Object(Closure), Array)
#6 /Users/azimsaibou/Desktop/php projects/sous-controle-docker/www/sous_controle/vendor/pestphp/pest/src/Factories/TestCaseFactory.php(169) : eval()'d code(35): P\Tests\Unit\ExceptionHandlerTest->__runTest(Object(Closure))
#7 /Users/azimsaibou/Desktop/php projects/sous-controle-docker/www/sous_controle/vendor/phpunit/phpunit/src/Framework/TestCase.php(1235): P\Tests\Unit\ExceptionHandlerTest->__pest_evaluable_it_print_a_generic_message_in_production_mode_when_a_page_not_found_exception_is_thrown()
#8 /Users/azimsaibou/Desktop/php projects/sous-controle-docker/www/sous_controle/vendor/phpunit/phpunit/src/Framework/TestCase.php(514): PHPUnit\Framework\TestCase->runTest()
#9 /Users/azimsaibou/Desktop/php projects/sous-controle-docker/www/sous_controle/vendor/phpunit/phpunit/src/Framework/TestRunner/TestRunner.php(87): PHPUnit\Framework\TestCase->runBare()
#10 /Users/azimsaibou/Desktop/php projects/sous-controle-docker/www/sous_controle/vendor/phpunit/phpunit/src/Framework/TestCase.php(361): PHPUnit\Framework\TestRunner->run(Object(P\Tests\Unit\ExceptionHandlerTest))
#11 /Users/azimsaibou/Desktop/php projects/sous-controle-docker/www/sous_controle/vendor/phpunit/phpunit/src/Framework/TestSuite.php(369): PHPUnit\Framework\TestCase->run()
#12 /Users/azimsaibou/Desktop/php projects/sous-controle-docker/www/sous_controle/vendor/phpunit/phpunit/src/Framework/TestSuite.php(369): PHPUnit\Framework\TestSuite->run()
#13 /Users/azimsaibou/Desktop/php projects/sous-controle-docker/www/sous_controle/vendor/phpunit/phpunit/src/Framework/TestSuite.php(369): PHPUnit\Framework\TestSuite->run()
#14 /Users/azimsaibou/Desktop/php projects/sous-controle-docker/www/sous_controle/vendor/phpunit/phpunit/src/TextUI/TestRunner.php(64): PHPUnit\Framework\TestSuite->run()
#15 /Users/azimsaibou/Desktop/php projects/sous-controle-docker/www/sous_controle/vendor/phpunit/phpunit/src/TextUI/Application.php(210): PHPUnit\TextUI\TestRunner->run(Object(PHPUnit\TextUI\Configuration\Configuration), Object(PHPUnit\Runner\ResultCache\DefaultResultCache), Object(PHPUnit\Framework\TestSuite))
#16 /Users/azimsaibou/Desktop/php projects/sous-controle-docker/www/sous_controle/vendor/pestphp/pest/src/Kernel.php(103): PHPUnit\TextUI\Application->run(Array)
#17 /Users/azimsaibou/Desktop/php projects/sous-controle-docker/www/sous_controle/vendor/pestphp/pest/bin/pest(184): Pest\Kernel->handle(Array, Array)
#18 /Users/azimsaibou/Desktop/php projects/sous-controle-docker/www/sous_controle/vendor/pestphp/pest/bin/pest(192): {closure:/Users/azimsaibou/Desktop/php projects/sous-controle-docker/www/sous_controle/vendor/pestphp/pest/bin/pest:18}()
#19 /Users/azimsaibou/Desktop/php projects/sous-controle-docker/www/sous_controle/vendor/bin/pest(119): include('/Users/azimsaib...')
#20 {main}

[2025-03-28 21:53:10] Exception: A Page Is Not Found 
in /Users/azimsaibou/Desktop/php projects/sous-controle-docker/www/sous_controle/tests/Unit/ExceptionHandlerTest.php 
on line 45
Trace: #0 /Users/azimsaibou/Desktop/php projects/sous-controle-docker/www/sous_controle/vendor/pestphp/pest/src/Factories/TestCaseMethodFactory.php(168): P\Tests\Unit\ExceptionHandlerTest->{closure:/Users/azimsaibou/Desktop/php projects/sous-controle-docker/www/sous_controle/tests/Unit/ExceptionHandlerTest.php:41}()
#1 [internal function]: P\Tests\Unit\ExceptionHandlerTest->{closure:Pest\Factories\TestCaseMethodFactory::getClosure():158}()
#2 /Users/azimsaibou/Desktop/php projects/sous-controle-docker/www/sous_controle/vendor/pestphp/pest/src/Concerns/Testable.php(419): call_user_func_array(Object(Closure), Array)
#3 /Users/azimsaibou/Desktop/php projects/sous-controle-docker/www/sous_controle/vendor/pestphp/pest/src/Support/ExceptionTrace.php(26): P\Tests\Unit\ExceptionHandlerTest->{closure:Pest\Concerns\Testable::__callClosure():419}()
#4 /Users/azimsaibou/Desktop/php projects/sous-controle-docker/www/sous_controle/vendor/pestphp/pest/src/Concerns/Testable.php(419): Pest\Support\ExceptionTrace::ensure(Object(Closure))
#5 /Users/azimsaibou/Desktop/php projects/sous-controle-docker/www/sous_controle/vendor/pestphp/pest/src/Concerns/Testable.php(321): P\Tests\Unit\ExceptionHandlerTest->__callClosure(Object(Closure), Array)
#6 /Users/azimsaibou/Desktop/php projects/sous-controle-docker/www/sous_controle/vendor/pestphp/pest/src/Factories/TestCaseFactory.php(169) : eval()'d code(44): P\Tests\Unit\ExceptionHandlerTest->__runTest(Object(Closure))
#7 /Users/azimsaibou/Desktop/php projects/sous-controle-docker/www/sous_controle/vendor/phpunit/phpunit/src/Framework/TestCase.php(1235): P\Tests\Unit\ExceptionHandlerTest->__pest_evaluable_it_print_a_generic_message_in_production_mode_when_other_exception_is_thrown()
#8 /Users/azimsaibou/Desktop/php projects/sous-controle-docker/www/sous_controle/vendor/phpunit/phpunit/src/Framework/TestCase.php(514): PHPUnit\Framework\TestCase->runTest()
#9 /Users/azimsaibou/Desktop/php projects/sous-controle-docker/www/sous_controle/vendor/phpunit/phpunit/src/Framework/TestRunner/TestRunner.php(87): PHPUnit\Framework\TestCase->runBare()
#10 /Users/azimsaibou/Desktop/php projects/sous-controle-docker/www/sous_controle/vendor/phpunit/phpunit/src/Framework/TestCase.php(361): PHPUnit\Framework\TestRunner->run(Object(P\Tests\Unit\ExceptionHandlerTest))
#11 /Users/azimsaibou/Desktop/php projects/sous-controle-docker/www/sous_controle/vendor/phpunit/phpunit/src/Framework/TestSuite.php(369): PHPUnit\Framework\TestCase->run()
#12 /Users/azimsaibou/Desktop/php projects/sous-controle-docker/www/sous_controle/vendor/phpunit/phpunit/src/Framework/TestSuite.php(369): PHPUnit\Framework\TestSuite->run()
#13 /Users/azimsaibou/Desktop/php projects/sous-controle-docker/www/sous_controle/vendor/phpunit/phpunit/src/Framework/TestSuite.php(369): PHPUnit\Framework\TestSuite->run()
#14 /Users/azimsaibou/Desktop/php projects/sous-controle-docker/www/sous_controle/vendor/phpunit/phpunit/src/TextUI/TestRunner.php(64): PHPUnit\Framework\TestSuite->run()
#15 /Users/azimsaibou/Desktop/php projects/sous-controle-docker/www/sous_controle/vendor/phpunit/phpunit/src/TextUI/Application.php(210): PHPUnit\TextUI\TestRunner->run(Object(PHPUnit\TextUI\Configuration\Configuration), Object(PHPUnit\Runner\ResultCache\DefaultResultCache), Object(PHPUnit\Framework\TestSuite))
#16 /Users/azimsaibou/Desktop/php projects/sous-controle-docker/www/sous_controle/vendor/pestphp/pest/src/Kernel.php(103): PHPUnit\TextUI\Application->run(Array)
#17 /Users/azimsaibou/Desktop/php projects/sous-controle-docker/www/sous_controle/vendor/pestphp/pest/bin/pest(184): Pest\Kernel->handle(Array, Array)
#18 /Users/azimsaibou/Desktop/php projects/sous-controle-docker/www/sous_controle/vendor/pestphp/pest/bin/pest(192): {closure:/Users/azimsaibou/Desktop/php projects/sous-controle-docker/www/sous_controle/vendor/pestphp/pest/bin/pest:18}()
#19 /Users/azimsaibou/Desktop/php projects/sous-controle-docker/www/sous_controle/vendor/bin/pest(119): include('/Users/azimsaib...')
#20 {main}

[2025-03-28 21:55:02] Exception: A Page Is Not Found 
in /Users/azimsaibou/Desktop/php projects/sous-controle-docker/www/sous_controle/tests/Unit/ExceptionHandlerTest.php 
on line 42
Trace: #0 /Users/azimsaibou/Desktop/php projects/sous-controle-docker/www/sous_controle/vendor/pestphp/pest/src/Factories/TestCaseMethodFactory.php(168): P\Tests\Unit\ExceptionHandlerTest->{closure:/Users/azimsaibou/Desktop/php projects/sous-controle-docker/www/sous_controle/tests/Unit/ExceptionHandlerTest.php:38}()
#1 [internal function]: P\Tests\Unit\ExceptionHandlerTest->{closure:Pest\Factories\TestCaseMethodFactory::getClosure():158}()
#2 /Users/azimsaibou/Desktop/php projects/sous-controle-docker/www/sous_controle/vendor/pestphp/pest/src/Concerns/Testable.php(419): call_user_func_array(Object(Closure), Array)
#3 /Users/azimsaibou/Desktop/php projects/sous-controle-docker/www/sous_controle/vendor/pestphp/pest/src/Support/ExceptionTrace.php(26): P\Tests\Unit\ExceptionHandlerTest->{closure:Pest\Concerns\Testable::__callClosure():419}()
#4 /Users/azimsaibou/Desktop/php projects/sous-controle-docker/www/sous_controle/vendor/pestphp/pest/src/Concerns/Testable.php(419): Pest\Support\ExceptionTrace::ensure(Object(Closure))
#5 /Users/azimsaibou/Desktop/php projects/sous-controle-docker/www/sous_controle/vendor/pestphp/pest/src/Concerns/Testable.php(321): P\Tests\Unit\ExceptionHandlerTest->__callClosure(Object(Closure), Array)
#6 /Users/azimsaibou/Desktop/php projects/sous-controle-docker/www/sous_controle/vendor/pestphp/pest/src/Factories/TestCaseFactory.php(169) : eval()'d code(35): P\Tests\Unit\ExceptionHandlerTest->__runTest(Object(Closure))
#7 /Users/azimsaibou/Desktop/php projects/sous-controle-docker/www/sous_controle/vendor/phpunit/phpunit/src/Framework/TestCase.php(1235): P\Tests\Unit\ExceptionHandlerTest->__pest_evaluable_it_print_a_generic_message_in_production_mode_when_a_page_not_found_exception_is_thrown()
#8 /Users/azimsaibou/Desktop/php projects/sous-controle-docker/www/sous_controle/vendor/phpunit/phpunit/src/Framework/TestCase.php(514): PHPUnit\Framework\TestCase->runTest()
#9 /Users/azimsaibou/Desktop/php projects/sous-controle-docker/www/sous_controle/vendor/phpunit/phpunit/src/Framework/TestRunner/TestRunner.php(87): PHPUnit\Framework\TestCase->runBare()
#10 /Users/azimsaibou/Desktop/php projects/sous-controle-docker/www/sous_controle/vendor/phpunit/phpunit/src/Framework/TestCase.php(361): PHPUnit\Framework\TestRunner->run(Object(P\Tests\Unit\ExceptionHandlerTest))
#11 /Users/azimsaibou/Desktop/php projects/sous-controle-docker/www/sous_controle/vendor/phpunit/phpunit/src/Framework/TestSuite.php(369): PHPUnit\Framework\TestCase->run()
#12 /Users/azimsaibou/Desktop/php projects/sous-controle-docker/www/sous_controle/vendor/phpunit/phpunit/src/Framework/TestSuite.php(369): PHPUnit\Framework\TestSuite->run()
#13 /Users/azimsaibou/Desktop/php projects/sous-controle-docker/www/sous_controle/vendor/phpunit/phpunit/src/Framework/TestSuite.php(369): PHPUnit\Framework\TestSuite->run()
#14 /Users/azimsaibou/Desktop/php projects/sous-controle-docker/www/sous_controle/vendor/phpunit/phpunit/src/TextUI/TestRunner.php(64): PHPUnit\Framework\TestSuite->run()
#15 /Users/azimsaibou/Desktop/php projects/sous-controle-docker/www/sous_controle/vendor/phpunit/phpunit/src/TextUI/Application.php(210): PHPUnit\TextUI\TestRunner->run(Object(PHPUnit\TextUI\Configuration\Configuration), Object(PHPUnit\Runner\ResultCache\DefaultResultCache), Object(PHPUnit\Framework\TestSuite))
#16 /Users/azimsaibou/Desktop/php projects/sous-controle-docker/www/sous_controle/vendor/pestphp/pest/src/Kernel.php(103): PHPUnit\TextUI\Application->run(Array)
#17 /Users/azimsaibou/Desktop/php projects/sous-controle-docker/www/sous_controle/vendor/pestphp/pest/bin/pest(184): Pest\Kernel->handle(Array, Array)
#18 /Users/azimsaibou/Desktop/php projects/sous-controle-docker/www/sous_controle/vendor/pestphp/pest/bin/pest(192): {closure:/Users/azimsaibou/Desktop/php projects/sous-controle-docker/www/sous_controle/vendor/pestphp/pest/bin/pest:18}()
#19 /Users/azimsaibou/Desktop/php projects/sous-controle-docker/www/sous_controle/vendor/bin/pest(119): include('/Users/azimsaib...')
#20 {main}

[2025-03-28 21:55:02] Exception: A Page Is Not Found 
in /Users/azimsaibou/Desktop/php projects/sous-controle-docker/www/sous_controle/tests/Unit/ExceptionHandlerTest.php 
on line 52
Trace: #0 /Users/azimsaibou/Desktop/php projects/sous-controle-docker/www/sous_controle/vendor/pestphp/pest/src/Factories/TestCaseMethodFactory.php(168): P\Tests\Unit\ExceptionHandlerTest->{closure:/Users/azimsaibou/Desktop/php projects/sous-controle-docker/www/sous_controle/tests/Unit/ExceptionHandlerTest.php:48}()
#1 [internal function]: P\Tests\Unit\ExceptionHandlerTest->{closure:Pest\Factories\TestCaseMethodFactory::getClosure():158}()
#2 /Users/azimsaibou/Desktop/php projects/sous-controle-docker/www/sous_controle/vendor/pestphp/pest/src/Concerns/Testable.php(419): call_user_func_array(Object(Closure), Array)
#3 /Users/azimsaibou/Desktop/php projects/sous-controle-docker/www/sous_controle/vendor/pestphp/pest/src/Support/ExceptionTrace.php(26): P\Tests\Unit\ExceptionHandlerTest->{closure:Pest\Concerns\Testable::__callClosure():419}()
#4 /Users/azimsaibou/Desktop/php projects/sous-controle-docker/www/sous_controle/vendor/pestphp/pest/src/Concerns/Testable.php(419): Pest\Support\ExceptionTrace::ensure(Object(Closure))
#5 /Users/azimsaibou/Desktop/php projects/sous-controle-docker/www/sous_controle/vendor/pestphp/pest/src/Concerns/Testable.php(321): P\Tests\Unit\ExceptionHandlerTest->__callClosure(Object(Closure), Array)
#6 /Users/azimsaibou/Desktop/php projects/sous-controle-docker/www/sous_controle/vendor/pestphp/pest/src/Factories/TestCaseFactory.php(169) : eval()'d code(44): P\Tests\Unit\ExceptionHandlerTest->__runTest(Object(Closure))
#7 /Users/azimsaibou/Desktop/php projects/sous-controle-docker/www/sous_controle/vendor/phpunit/phpunit/src/Framework/TestCase.php(1235): P\Tests\Unit\ExceptionHandlerTest->__pest_evaluable_it_print_a_generic_message_in_production_mode_when_other_exception_is_thrown()
#8 /Users/azimsaibou/Desktop/php projects/sous-controle-docker/www/sous_controle/vendor/phpunit/phpunit/src/Framework/TestCase.php(514): PHPUnit\Framework\TestCase->runTest()
#9 /Users/azimsaibou/Desktop/php projects/sous-controle-docker/www/sous_controle/vendor/phpunit/phpunit/src/Framework/TestRunner/TestRunner.php(87): PHPUnit\Framework\TestCase->runBare()
#10 /Users/azimsaibou/Desktop/php projects/sous-controle-docker/www/sous_controle/vendor/phpunit/phpunit/src/Framework/TestCase.php(361): PHPUnit\Framework\TestRunner->run(Object(P\Tests\Unit\ExceptionHandlerTest))
#11 /Users/azimsaibou/Desktop/php projects/sous-controle-docker/www/sous_controle/vendor/phpunit/phpunit/src/Framework/TestSuite.php(369): PHPUnit\Framework\TestCase->run()
#12 /Users/azimsaibou/Desktop/php projects/sous-controle-docker/www/sous_controle/vendor/phpunit/phpunit/src/Framework/TestSuite.php(369): PHPUnit\Framework\TestSuite->run()
#13 /Users/azimsaibou/Desktop/php projects/sous-controle-docker/www/sous_controle/vendor/phpunit/phpunit/src/Framework/TestSuite.php(369): PHPUnit\Framework\TestSuite->run()
#14 /Users/azimsaibou/Desktop/php projects/sous-controle-docker/www/sous_controle/vendor/phpunit/phpunit/src/TextUI/TestRunner.php(64): PHPUnit\Framework\TestSuite->run()
#15 /Users/azimsaibou/Desktop/php projects/sous-controle-docker/www/sous_controle/vendor/phpunit/phpunit/src/TextUI/Application.php(210): PHPUnit\TextUI\TestRunner->run(Object(PHPUnit\TextUI\Configuration\Configuration), Object(PHPUnit\Runner\ResultCache\DefaultResultCache), Object(PHPUnit\Framework\TestSuite))
#16 /Users/azimsaibou/Desktop/php projects/sous-controle-docker/www/sous_controle/vendor/pestphp/pest/src/Kernel.php(103): PHPUnit\TextUI\Application->run(Array)
#17 /Users/azimsaibou/Desktop/php projects/sous-controle-docker/www/sous_controle/vendor/pestphp/pest/bin/pest(184): Pest\Kernel->handle(Array, Array)
#18 /Users/azimsaibou/Desktop/php projects/sous-controle-docker/www/sous_controle/vendor/pestphp/pest/bin/pest(192): {closure:/Users/azimsaibou/Desktop/php projects/sous-controle-docker/www/sous_controle/vendor/pestphp/pest/bin/pest:18}()
#19 /Users/azimsaibou/Desktop/php projects/sous-controle-docker/www/sous_controle/vendor/bin/pest(119): include('/Users/azimsaib...')
#20 {main}

[2025-03-28 21:55:02] Exception: Test error 
in /Users/azimsaibou/Desktop/php projects/sous-controle-docker/www/sous_controle/tests/Unit/ExceptionHandlerTest.php 
on line 64
Trace: #0 /Users/azimsaibou/Desktop/php projects/sous-controle-docker/www/sous_controle/vendor/pestphp/pest/src/Factories/TestCaseMethodFactory.php(168): P\Tests\Unit\ExceptionHandlerTest->{closure:/Users/azimsaibou/Desktop/php projects/sous-controle-docker/www/sous_controle/tests/Unit/ExceptionHandlerTest.php:58}()
#1 [internal function]: P\Tests\Unit\ExceptionHandlerTest->{closure:Pest\Factories\TestCaseMethodFactory::getClosure():158}()
#2 /Users/azimsaibou/Desktop/php projects/sous-controle-docker/www/sous_controle/vendor/pestphp/pest/src/Concerns/Testable.php(419): call_user_func_array(Object(Closure), Array)
#3 /Users/azimsaibou/Desktop/php projects/sous-controle-docker/www/sous_controle/vendor/pestphp/pest/src/Support/ExceptionTrace.php(26): P\Tests\Unit\ExceptionHandlerTest->{closure:Pest\Concerns\Testable::__callClosure():419}()
#4 /Users/azimsaibou/Desktop/php projects/sous-controle-docker/www/sous_controle/vendor/pestphp/pest/src/Concerns/Testable.php(419): Pest\Support\ExceptionTrace::ensure(Object(Closure))
#5 /Users/azimsaibou/Desktop/php projects/sous-controle-docker/www/sous_controle/vendor/pestphp/pest/src/Concerns/Testable.php(321): P\Tests\Unit\ExceptionHandlerTest->__callClosure(Object(Closure), Array)
#6 /Users/azimsaibou/Desktop/php projects/sous-controle-docker/www/sous_controle/vendor/pestphp/pest/src/Factories/TestCaseFactory.php(169) : eval()'d code(53): P\Tests\Unit\ExceptionHandlerTest->__runTest(Object(Closure))
#7 /Users/azimsaibou/Desktop/php projects/sous-controle-docker/www/sous_controle/vendor/phpunit/phpunit/src/Framework/TestCase.php(1235): P\Tests\Unit\ExceptionHandlerTest->__pest_evaluable_ExceptionHandler_sets_HTTP_status_code_500()
#8 /Users/azimsaibou/Desktop/php projects/sous-controle-docker/www/sous_controle/vendor/phpunit/phpunit/src/Framework/TestCase.php(514): PHPUnit\Framework\TestCase->runTest()
#9 /Users/azimsaibou/Desktop/php projects/sous-controle-docker/www/sous_controle/vendor/phpunit/phpunit/src/Framework/TestRunner/TestRunner.php(87): PHPUnit\Framework\TestCase->runBare()
#10 /Users/azimsaibou/Desktop/php projects/sous-controle-docker/www/sous_controle/vendor/phpunit/phpunit/src/Framework/TestCase.php(361): PHPUnit\Framework\TestRunner->run(Object(P\Tests\Unit\ExceptionHandlerTest))
#11 /Users/azimsaibou/Desktop/php projects/sous-controle-docker/www/sous_controle/vendor/phpunit/phpunit/src/Framework/TestSuite.php(369): PHPUnit\Framework\TestCase->run()
#12 /Users/azimsaibou/Desktop/php projects/sous-controle-docker/www/sous_controle/vendor/phpunit/phpunit/src/Framework/TestSuite.php(369): PHPUnit\Framework\TestSuite->run()
#13 /Users/azimsaibou/Desktop/php projects/sous-controle-docker/www/sous_controle/vendor/phpunit/phpunit/src/Framework/TestSuite.php(369): PHPUnit\Framework\TestSuite->run()
#14 /Users/azimsaibou/Desktop/php projects/sous-controle-docker/www/sous_controle/vendor/phpunit/phpunit/src/TextUI/TestRunner.php(64): PHPUnit\Framework\TestSuite->run()
#15 /Users/azimsaibou/Desktop/php projects/sous-controle-docker/www/sous_controle/vendor/phpunit/phpunit/src/TextUI/Application.php(210): PHPUnit\TextUI\TestRunner->run(Object(PHPUnit\TextUI\Configuration\Configuration), Object(PHPUnit\Runner\ResultCache\DefaultResultCache), Object(PHPUnit\Framework\TestSuite))
#16 /Users/azimsaibou/Desktop/php projects/sous-controle-docker/www/sous_controle/vendor/pestphp/pest/src/Kernel.php(103): PHPUnit\TextUI\Application->run(Array)
#17 /Users/azimsaibou/Desktop/php projects/sous-controle-docker/www/sous_controle/vendor/pestphp/pest/bin/pest(184): Pest\Kernel->handle(Array, Array)
#18 /Users/azimsaibou/Desktop/php projects/sous-controle-docker/www/sous_controle/vendor/pestphp/pest/bin/pest(192): {closure:/Users/azimsaibou/Desktop/php projects/sous-controle-docker/www/sous_controle/vendor/pestphp/pest/bin/pest:18}()
#19 /Users/azimsaibou/Desktop/php projects/sous-controle-docker/www/sous_controle/vendor/bin/pest(119): include('/Users/azimsaib...')
#20 {main}

[2025-03-28 21:55:41] Exception: A Page Is Not Found 
in /Users/azimsaibou/Desktop/php projects/sous-controle-docker/www/sous_controle/tests/Unit/ExceptionHandlerTest.php 
on line 42
Trace: #0 /Users/azimsaibou/Desktop/php projects/sous-controle-docker/www/sous_controle/vendor/pestphp/pest/src/Factories/TestCaseMethodFactory.php(168): P\Tests\Unit\ExceptionHandlerTest->{closure:/Users/azimsaibou/Desktop/php projects/sous-controle-docker/www/sous_controle/tests/Unit/ExceptionHandlerTest.php:38}()
#1 [internal function]: P\Tests\Unit\ExceptionHandlerTest->{closure:Pest\Factories\TestCaseMethodFactory::getClosure():158}()
#2 /Users/azimsaibou/Desktop/php projects/sous-controle-docker/www/sous_controle/vendor/pestphp/pest/src/Concerns/Testable.php(419): call_user_func_array(Object(Closure), Array)
#3 /Users/azimsaibou/Desktop/php projects/sous-controle-docker/www/sous_controle/vendor/pestphp/pest/src/Support/ExceptionTrace.php(26): P\Tests\Unit\ExceptionHandlerTest->{closure:Pest\Concerns\Testable::__callClosure():419}()
#4 /Users/azimsaibou/Desktop/php projects/sous-controle-docker/www/sous_controle/vendor/pestphp/pest/src/Concerns/Testable.php(419): Pest\Support\ExceptionTrace::ensure(Object(Closure))
#5 /Users/azimsaibou/Desktop/php projects/sous-controle-docker/www/sous_controle/vendor/pestphp/pest/src/Concerns/Testable.php(321): P\Tests\Unit\ExceptionHandlerTest->__callClosure(Object(Closure), Array)
#6 /Users/azimsaibou/Desktop/php projects/sous-controle-docker/www/sous_controle/vendor/pestphp/pest/src/Factories/TestCaseFactory.php(169) : eval()'d code(35): P\Tests\Unit\ExceptionHandlerTest->__runTest(Object(Closure))
#7 /Users/azimsaibou/Desktop/php projects/sous-controle-docker/www/sous_controle/vendor/phpunit/phpunit/src/Framework/TestCase.php(1235): P\Tests\Unit\ExceptionHandlerTest->__pest_evaluable_it_print_a_generic_message_in_production_mode_when_a_page_not_found_exception_is_thrown()
#8 /Users/azimsaibou/Desktop/php projects/sous-controle-docker/www/sous_controle/vendor/phpunit/phpunit/src/Framework/TestCase.php(514): PHPUnit\Framework\TestCase->runTest()
#9 /Users/azimsaibou/Desktop/php projects/sous-controle-docker/www/sous_controle/vendor/phpunit/phpunit/src/Framework/TestRunner/TestRunner.php(87): PHPUnit\Framework\TestCase->runBare()
#10 /Users/azimsaibou/Desktop/php projects/sous-controle-docker/www/sous_controle/vendor/phpunit/phpunit/src/Framework/TestCase.php(361): PHPUnit\Framework\TestRunner->run(Object(P\Tests\Unit\ExceptionHandlerTest))
#11 /Users/azimsaibou/Desktop/php projects/sous-controle-docker/www/sous_controle/vendor/phpunit/phpunit/src/Framework/TestSuite.php(369): PHPUnit\Framework\TestCase->run()
#12 /Users/azimsaibou/Desktop/php projects/sous-controle-docker/www/sous_controle/vendor/phpunit/phpunit/src/Framework/TestSuite.php(369): PHPUnit\Framework\TestSuite->run()
#13 /Users/azimsaibou/Desktop/php projects/sous-controle-docker/www/sous_controle/vendor/phpunit/phpunit/src/Framework/TestSuite.php(369): PHPUnit\Framework\TestSuite->run()
#14 /Users/azimsaibou/Desktop/php projects/sous-controle-docker/www/sous_controle/vendor/phpunit/phpunit/src/TextUI/TestRunner.php(64): PHPUnit\Framework\TestSuite->run()
#15 /Users/azimsaibou/Desktop/php projects/sous-controle-docker/www/sous_controle/vendor/phpunit/phpunit/src/TextUI/Application.php(210): PHPUnit\TextUI\TestRunner->run(Object(PHPUnit\TextUI\Configuration\Configuration), Object(PHPUnit\Runner\ResultCache\DefaultResultCache), Object(PHPUnit\Framework\TestSuite))
#16 /Users/azimsaibou/Desktop/php projects/sous-controle-docker/www/sous_controle/vendor/pestphp/pest/src/Kernel.php(103): PHPUnit\TextUI\Application->run(Array)
#17 /Users/azimsaibou/Desktop/php projects/sous-controle-docker/www/sous_controle/vendor/pestphp/pest/bin/pest(184): Pest\Kernel->handle(Array, Array)
#18 /Users/azimsaibou/Desktop/php projects/sous-controle-docker/www/sous_controle/vendor/pestphp/pest/bin/pest(192): {closure:/Users/azimsaibou/Desktop/php projects/sous-controle-docker/www/sous_controle/vendor/pestphp/pest/bin/pest:18}()
#19 /Users/azimsaibou/Desktop/php projects/sous-controle-docker/www/sous_controle/vendor/bin/pest(119): include('/Users/azimsaib...')
#20 {main}

[2025-03-28 21:55:41] Exception: A Page Is Not Found 
in /Users/azimsaibou/Desktop/php projects/sous-controle-docker/www/sous_controle/tests/Unit/ExceptionHandlerTest.php 
on line 52
Trace: #0 /Users/azimsaibou/Desktop/php projects/sous-controle-docker/www/sous_controle/vendor/pestphp/pest/src/Factories/TestCaseMethodFactory.php(168): P\Tests\Unit\ExceptionHandlerTest->{closure:/Users/azimsaibou/Desktop/php projects/sous-controle-docker/www/sous_controle/tests/Unit/ExceptionHandlerTest.php:48}()
#1 [internal function]: P\Tests\Unit\ExceptionHandlerTest->{closure:Pest\Factories\TestCaseMethodFactory::getClosure():158}()
#2 /Users/azimsaibou/Desktop/php projects/sous-controle-docker/www/sous_controle/vendor/pestphp/pest/src/Concerns/Testable.php(419): call_user_func_array(Object(Closure), Array)
#3 /Users/azimsaibou/Desktop/php projects/sous-controle-docker/www/sous_controle/vendor/pestphp/pest/src/Support/ExceptionTrace.php(26): P\Tests\Unit\ExceptionHandlerTest->{closure:Pest\Concerns\Testable::__callClosure():419}()
#4 /Users/azimsaibou/Desktop/php projects/sous-controle-docker/www/sous_controle/vendor/pestphp/pest/src/Concerns/Testable.php(419): Pest\Support\ExceptionTrace::ensure(Object(Closure))
#5 /Users/azimsaibou/Desktop/php projects/sous-controle-docker/www/sous_controle/vendor/pestphp/pest/src/Concerns/Testable.php(321): P\Tests\Unit\ExceptionHandlerTest->__callClosure(Object(Closure), Array)
#6 /Users/azimsaibou/Desktop/php projects/sous-controle-docker/www/sous_controle/vendor/pestphp/pest/src/Factories/TestCaseFactory.php(169) : eval()'d code(44): P\Tests\Unit\ExceptionHandlerTest->__runTest(Object(Closure))
#7 /Users/azimsaibou/Desktop/php projects/sous-controle-docker/www/sous_controle/vendor/phpunit/phpunit/src/Framework/TestCase.php(1235): P\Tests\Unit\ExceptionHandlerTest->__pest_evaluable_it_print_a_generic_message_in_production_mode_when_other_exception_is_thrown()
#8 /Users/azimsaibou/Desktop/php projects/sous-controle-docker/www/sous_controle/vendor/phpunit/phpunit/src/Framework/TestCase.php(514): PHPUnit\Framework\TestCase->runTest()
#9 /Users/azimsaibou/Desktop/php projects/sous-controle-docker/www/sous_controle/vendor/phpunit/phpunit/src/Framework/TestRunner/TestRunner.php(87): PHPUnit\Framework\TestCase->runBare()
#10 /Users/azimsaibou/Desktop/php projects/sous-controle-docker/www/sous_controle/vendor/phpunit/phpunit/src/Framework/TestCase.php(361): PHPUnit\Framework\TestRunner->run(Object(P\Tests\Unit\ExceptionHandlerTest))
#11 /Users/azimsaibou/Desktop/php projects/sous-controle-docker/www/sous_controle/vendor/phpunit/phpunit/src/Framework/TestSuite.php(369): PHPUnit\Framework\TestCase->run()
#12 /Users/azimsaibou/Desktop/php projects/sous-controle-docker/www/sous_controle/vendor/phpunit/phpunit/src/Framework/TestSuite.php(369): PHPUnit\Framework\TestSuite->run()
#13 /Users/azimsaibou/Desktop/php projects/sous-controle-docker/www/sous_controle/vendor/phpunit/phpunit/src/Framework/TestSuite.php(369): PHPUnit\Framework\TestSuite->run()
#14 /Users/azimsaibou/Desktop/php projects/sous-controle-docker/www/sous_controle/vendor/phpunit/phpunit/src/TextUI/TestRunner.php(64): PHPUnit\Framework\TestSuite->run()
#15 /Users/azimsaibou/Desktop/php projects/sous-controle-docker/www/sous_controle/vendor/phpunit/phpunit/src/TextUI/Application.php(210): PHPUnit\TextUI\TestRunner->run(Object(PHPUnit\TextUI\Configuration\Configuration), Object(PHPUnit\Runner\ResultCache\DefaultResultCache), Object(PHPUnit\Framework\TestSuite))
#16 /Users/azimsaibou/Desktop/php projects/sous-controle-docker/www/sous_controle/vendor/pestphp/pest/src/Kernel.php(103): PHPUnit\TextUI\Application->run(Array)
#17 /Users/azimsaibou/Desktop/php projects/sous-controle-docker/www/sous_controle/vendor/pestphp/pest/bin/pest(184): Pest\Kernel->handle(Array, Array)
#18 /Users/azimsaibou/Desktop/php projects/sous-controle-docker/www/sous_controle/vendor/pestphp/pest/bin/pest(192): {closure:/Users/azimsaibou/Desktop/php projects/sous-controle-docker/www/sous_controle/vendor/pestphp/pest/bin/pest:18}()
#19 /Users/azimsaibou/Desktop/php projects/sous-controle-docker/www/sous_controle/vendor/bin/pest(119): include('/Users/azimsaib...')
#20 {main}

[2025-03-28 21:55:41] Exception: Test error 
in /Users/azimsaibou/Desktop/php projects/sous-controle-docker/www/sous_controle/tests/Unit/ExceptionHandlerTest.php 
on line 64
Trace: #0 /Users/azimsaibou/Desktop/php projects/sous-controle-docker/www/sous_controle/vendor/pestphp/pest/src/Factories/TestCaseMethodFactory.php(168): P\Tests\Unit\ExceptionHandlerTest->{closure:/Users/azimsaibou/Desktop/php projects/sous-controle-docker/www/sous_controle/tests/Unit/ExceptionHandlerTest.php:58}()
#1 [internal function]: P\Tests\Unit\ExceptionHandlerTest->{closure:Pest\Factories\TestCaseMethodFactory::getClosure():158}()
#2 /Users/azimsaibou/Desktop/php projects/sous-controle-docker/www/sous_controle/vendor/pestphp/pest/src/Concerns/Testable.php(419): call_user_func_array(Object(Closure), Array)
#3 /Users/azimsaibou/Desktop/php projects/sous-controle-docker/www/sous_controle/vendor/pestphp/pest/src/Support/ExceptionTrace.php(26): P\Tests\Unit\ExceptionHandlerTest->{closure:Pest\Concerns\Testable::__callClosure():419}()
#4 /Users/azimsaibou/Desktop/php projects/sous-controle-docker/www/sous_controle/vendor/pestphp/pest/src/Concerns/Testable.php(419): Pest\Support\ExceptionTrace::ensure(Object(Closure))
#5 /Users/azimsaibou/Desktop/php projects/sous-controle-docker/www/sous_controle/vendor/pestphp/pest/src/Concerns/Testable.php(321): P\Tests\Unit\ExceptionHandlerTest->__callClosure(Object(Closure), Array)
#6 /Users/azimsaibou/Desktop/php projects/sous-controle-docker/www/sous_controle/vendor/pestphp/pest/src/Factories/TestCaseFactory.php(169) : eval()'d code(53): P\Tests\Unit\ExceptionHandlerTest->__runTest(Object(Closure))
#7 /Users/azimsaibou/Desktop/php projects/sous-controle-docker/www/sous_controle/vendor/phpunit/phpunit/src/Framework/TestCase.php(1235): P\Tests\Unit\ExceptionHandlerTest->__pest_evaluable_ExceptionHandler_sets_HTTP_status_code_500()
#8 /Users/azimsaibou/Desktop/php projects/sous-controle-docker/www/sous_controle/vendor/phpunit/phpunit/src/Framework/TestCase.php(514): PHPUnit\Framework\TestCase->runTest()
#9 /Users/azimsaibou/Desktop/php projects/sous-controle-docker/www/sous_controle/vendor/phpunit/phpunit/src/Framework/TestRunner/TestRunner.php(87): PHPUnit\Framework\TestCase->runBare()
#10 /Users/azimsaibou/Desktop/php projects/sous-controle-docker/www/sous_controle/vendor/phpunit/phpunit/src/Framework/TestCase.php(361): PHPUnit\Framework\TestRunner->run(Object(P\Tests\Unit\ExceptionHandlerTest))
#11 /Users/azimsaibou/Desktop/php projects/sous-controle-docker/www/sous_controle/vendor/phpunit/phpunit/src/Framework/TestSuite.php(369): PHPUnit\Framework\TestCase->run()
#12 /Users/azimsaibou/Desktop/php projects/sous-controle-docker/www/sous_controle/vendor/phpunit/phpunit/src/Framework/TestSuite.php(369): PHPUnit\Framework\TestSuite->run()
#13 /Users/azimsaibou/Desktop/php projects/sous-controle-docker/www/sous_controle/vendor/phpunit/phpunit/src/Framework/TestSuite.php(369): PHPUnit\Framework\TestSuite->run()
#14 /Users/azimsaibou/Desktop/php projects/sous-controle-docker/www/sous_controle/vendor/phpunit/phpunit/src/TextUI/TestRunner.php(64): PHPUnit\Framework\TestSuite->run()
#15 /Users/azimsaibou/Desktop/php projects/sous-controle-docker/www/sous_controle/vendor/phpunit/phpunit/src/TextUI/Application.php(210): PHPUnit\TextUI\TestRunner->run(Object(PHPUnit\TextUI\Configuration\Configuration), Object(PHPUnit\Runner\ResultCache\DefaultResultCache), Object(PHPUnit\Framework\TestSuite))
#16 /Users/azimsaibou/Desktop/php projects/sous-controle-docker/www/sous_controle/vendor/pestphp/pest/src/Kernel.php(103): PHPUnit\TextUI\Application->run(Array)
#17 /Users/azimsaibou/Desktop/php projects/sous-controle-docker/www/sous_controle/vendor/pestphp/pest/bin/pest(184): Pest\Kernel->handle(Array, Array)
#18 /Users/azimsaibou/Desktop/php projects/sous-controle-docker/www/sous_controle/vendor/pestphp/pest/bin/pest(192): {closure:/Users/azimsaibou/Desktop/php projects/sous-controle-docker/www/sous_controle/vendor/pestphp/pest/bin/pest:18}()
#19 /Users/azimsaibou/Desktop/php projects/sous-controle-docker/www/sous_controle/vendor/bin/pest(119): include('/Users/azimsaib...')
#20 {main}

[2025-03-28 22:36:29] Exception: A Page Is Not Found 
in /Users/azimsaibou/Desktop/php projects/sous-controle-docker/www/sous_controle/tests/Unit/ExceptionHandlerTest.php 
on line 42
Trace: #0 /Users/azimsaibou/Desktop/php projects/sous-controle-docker/www/sous_controle/vendor/pestphp/pest/src/Factories/TestCaseMethodFactory.php(168): P\Tests\Unit\ExceptionHandlerTest->{closure:/Users/azimsaibou/Desktop/php projects/sous-controle-docker/www/sous_controle/tests/Unit/ExceptionHandlerTest.php:38}()
#1 [internal function]: P\Tests\Unit\ExceptionHandlerTest->{closure:Pest\Factories\TestCaseMethodFactory::getClosure():158}()
#2 /Users/azimsaibou/Desktop/php projects/sous-controle-docker/www/sous_controle/vendor/pestphp/pest/src/Concerns/Testable.php(419): call_user_func_array(Object(Closure), Array)
#3 /Users/azimsaibou/Desktop/php projects/sous-controle-docker/www/sous_controle/vendor/pestphp/pest/src/Support/ExceptionTrace.php(26): P\Tests\Unit\ExceptionHandlerTest->{closure:Pest\Concerns\Testable::__callClosure():419}()
#4 /Users/azimsaibou/Desktop/php projects/sous-controle-docker/www/sous_controle/vendor/pestphp/pest/src/Concerns/Testable.php(419): Pest\Support\ExceptionTrace::ensure(Object(Closure))
#5 /Users/azimsaibou/Desktop/php projects/sous-controle-docker/www/sous_controle/vendor/pestphp/pest/src/Concerns/Testable.php(321): P\Tests\Unit\ExceptionHandlerTest->__callClosure(Object(Closure), Array)
#6 /Users/azimsaibou/Desktop/php projects/sous-controle-docker/www/sous_controle/vendor/pestphp/pest/src/Factories/TestCaseFactory.php(169) : eval()'d code(35): P\Tests\Unit\ExceptionHandlerTest->__runTest(Object(Closure))
#7 /Users/azimsaibou/Desktop/php projects/sous-controle-docker/www/sous_controle/vendor/phpunit/phpunit/src/Framework/TestCase.php(1235): P\Tests\Unit\ExceptionHandlerTest->__pest_evaluable_it_print_a_generic_message_in_production_mode_when_a_page_not_found_exception_is_thrown()
#8 /Users/azimsaibou/Desktop/php projects/sous-controle-docker/www/sous_controle/vendor/phpunit/phpunit/src/Framework/TestCase.php(514): PHPUnit\Framework\TestCase->runTest()
#9 /Users/azimsaibou/Desktop/php projects/sous-controle-docker/www/sous_controle/vendor/phpunit/phpunit/src/Framework/TestRunner/TestRunner.php(87): PHPUnit\Framework\TestCase->runBare()
#10 /Users/azimsaibou/Desktop/php projects/sous-controle-docker/www/sous_controle/vendor/phpunit/phpunit/src/Framework/TestCase.php(361): PHPUnit\Framework\TestRunner->run(Object(P\Tests\Unit\ExceptionHandlerTest))
#11 /Users/azimsaibou/Desktop/php projects/sous-controle-docker/www/sous_controle/vendor/phpunit/phpunit/src/Framework/TestSuite.php(369): PHPUnit\Framework\TestCase->run()
#12 /Users/azimsaibou/Desktop/php projects/sous-controle-docker/www/sous_controle/vendor/phpunit/phpunit/src/Framework/TestSuite.php(369): PHPUnit\Framework\TestSuite->run()
#13 /Users/azimsaibou/Desktop/php projects/sous-controle-docker/www/sous_controle/vendor/phpunit/phpunit/src/Framework/TestSuite.php(369): PHPUnit\Framework\TestSuite->run()
#14 /Users/azimsaibou/Desktop/php projects/sous-controle-docker/www/sous_controle/vendor/phpunit/phpunit/src/TextUI/TestRunner.php(64): PHPUnit\Framework\TestSuite->run()
#15 /Users/azimsaibou/Desktop/php projects/sous-controle-docker/www/sous_controle/vendor/phpunit/phpunit/src/TextUI/Application.php(210): PHPUnit\TextUI\TestRunner->run(Object(PHPUnit\TextUI\Configuration\Configuration), Object(PHPUnit\Runner\ResultCache\DefaultResultCache), Object(PHPUnit\Framework\TestSuite))
#16 /Users/azimsaibou/Desktop/php projects/sous-controle-docker/www/sous_controle/vendor/pestphp/pest/src/Kernel.php(103): PHPUnit\TextUI\Application->run(Array)
#17 /Users/azimsaibou/Desktop/php projects/sous-controle-docker/www/sous_controle/vendor/pestphp/pest/bin/pest(184): Pest\Kernel->handle(Array, Array)
#18 /Users/azimsaibou/Desktop/php projects/sous-controle-docker/www/sous_controle/vendor/pestphp/pest/bin/pest(192): {closure:/Users/azimsaibou/Desktop/php projects/sous-controle-docker/www/sous_controle/vendor/pestphp/pest/bin/pest:18}()
#19 /Users/azimsaibou/Desktop/php projects/sous-controle-docker/www/sous_controle/vendor/bin/pest(119): include('/Users/azimsaib...')
#20 {main}

[2025-03-28 22:36:29] Exception: A Page Is Not Found 
in /Users/azimsaibou/Desktop/php projects/sous-controle-docker/www/sous_controle/tests/Unit/ExceptionHandlerTest.php 
on line 52
Trace: #0 /Users/azimsaibou/Desktop/php projects/sous-controle-docker/www/sous_controle/vendor/pestphp/pest/src/Factories/TestCaseMethodFactory.php(168): P\Tests\Unit\ExceptionHandlerTest->{closure:/Users/azimsaibou/Desktop/php projects/sous-controle-docker/www/sous_controle/tests/Unit/ExceptionHandlerTest.php:48}()
#1 [internal function]: P\Tests\Unit\ExceptionHandlerTest->{closure:Pest\Factories\TestCaseMethodFactory::getClosure():158}()
#2 /Users/azimsaibou/Desktop/php projects/sous-controle-docker/www/sous_controle/vendor/pestphp/pest/src/Concerns/Testable.php(419): call_user_func_array(Object(Closure), Array)
#3 /Users/azimsaibou/Desktop/php projects/sous-controle-docker/www/sous_controle/vendor/pestphp/pest/src/Support/ExceptionTrace.php(26): P\Tests\Unit\ExceptionHandlerTest->{closure:Pest\Concerns\Testable::__callClosure():419}()
#4 /Users/azimsaibou/Desktop/php projects/sous-controle-docker/www/sous_controle/vendor/pestphp/pest/src/Concerns/Testable.php(419): Pest\Support\ExceptionTrace::ensure(Object(Closure))
#5 /Users/azimsaibou/Desktop/php projects/sous-controle-docker/www/sous_controle/vendor/pestphp/pest/src/Concerns/Testable.php(321): P\Tests\Unit\ExceptionHandlerTest->__callClosure(Object(Closure), Array)
#6 /Users/azimsaibou/Desktop/php projects/sous-controle-docker/www/sous_controle/vendor/pestphp/pest/src/Factories/TestCaseFactory.php(169) : eval()'d code(44): P\Tests\Unit\ExceptionHandlerTest->__runTest(Object(Closure))
#7 /Users/azimsaibou/Desktop/php projects/sous-controle-docker/www/sous_controle/vendor/phpunit/phpunit/src/Framework/TestCase.php(1235): P\Tests\Unit\ExceptionHandlerTest->__pest_evaluable_it_print_a_generic_message_in_production_mode_when_other_exception_is_thrown()
#8 /Users/azimsaibou/Desktop/php projects/sous-controle-docker/www/sous_controle/vendor/phpunit/phpunit/src/Framework/TestCase.php(514): PHPUnit\Framework\TestCase->runTest()
#9 /Users/azimsaibou/Desktop/php projects/sous-controle-docker/www/sous_controle/vendor/phpunit/phpunit/src/Framework/TestRunner/TestRunner.php(87): PHPUnit\Framework\TestCase->runBare()
#10 /Users/azimsaibou/Desktop/php projects/sous-controle-docker/www/sous_controle/vendor/phpunit/phpunit/src/Framework/TestCase.php(361): PHPUnit\Framework\TestRunner->run(Object(P\Tests\Unit\ExceptionHandlerTest))
#11 /Users/azimsaibou/Desktop/php projects/sous-controle-docker/www/sous_controle/vendor/phpunit/phpunit/src/Framework/TestSuite.php(369): PHPUnit\Framework\TestCase->run()
#12 /Users/azimsaibou/Desktop/php projects/sous-controle-docker/www/sous_controle/vendor/phpunit/phpunit/src/Framework/TestSuite.php(369): PHPUnit\Framework\TestSuite->run()
#13 /Users/azimsaibou/Desktop/php projects/sous-controle-docker/www/sous_controle/vendor/phpunit/phpunit/src/Framework/TestSuite.php(369): PHPUnit\Framework\TestSuite->run()
#14 /Users/azimsaibou/Desktop/php projects/sous-controle-docker/www/sous_controle/vendor/phpunit/phpunit/src/TextUI/TestRunner.php(64): PHPUnit\Framework\TestSuite->run()
#15 /Users/azimsaibou/Desktop/php projects/sous-controle-docker/www/sous_controle/vendor/phpunit/phpunit/src/TextUI/Application.php(210): PHPUnit\TextUI\TestRunner->run(Object(PHPUnit\TextUI\Configuration\Configuration), Object(PHPUnit\Runner\ResultCache\DefaultResultCache), Object(PHPUnit\Framework\TestSuite))
#16 /Users/azimsaibou/Desktop/php projects/sous-controle-docker/www/sous_controle/vendor/pestphp/pest/src/Kernel.php(103): PHPUnit\TextUI\Application->run(Array)
#17 /Users/azimsaibou/Desktop/php projects/sous-controle-docker/www/sous_controle/vendor/pestphp/pest/bin/pest(184): Pest\Kernel->handle(Array, Array)
#18 /Users/azimsaibou/Desktop/php projects/sous-controle-docker/www/sous_controle/vendor/pestphp/pest/bin/pest(192): {closure:/Users/azimsaibou/Desktop/php projects/sous-controle-docker/www/sous_controle/vendor/pestphp/pest/bin/pest:18}()
#19 /Users/azimsaibou/Desktop/php projects/sous-controle-docker/www/sous_controle/vendor/bin/pest(119): include('/Users/azimsaib...')
#20 {main}

[2025-03-28 22:36:29] Exception: Test error 
in /Users/azimsaibou/Desktop/php projects/sous-controle-docker/www/sous_controle/tests/Unit/ExceptionHandlerTest.php 
on line 65
Trace: #0 /Users/azimsaibou/Desktop/php projects/sous-controle-docker/www/sous_controle/vendor/pestphp/pest/src/Factories/TestCaseMethodFactory.php(168): P\Tests\Unit\ExceptionHandlerTest->{closure:/Users/azimsaibou/Desktop/php projects/sous-controle-docker/www/sous_controle/tests/Unit/ExceptionHandlerTest.php:62}()
#1 [internal function]: P\Tests\Unit\ExceptionHandlerTest->{closure:Pest\Factories\TestCaseMethodFactory::getClosure():158}()
#2 /Users/azimsaibou/Desktop/php projects/sous-controle-docker/www/sous_controle/vendor/pestphp/pest/src/Concerns/Testable.php(419): call_user_func_array(Object(Closure), Array)
#3 /Users/azimsaibou/Desktop/php projects/sous-controle-docker/www/sous_controle/vendor/pestphp/pest/src/Support/ExceptionTrace.php(26): P\Tests\Unit\ExceptionHandlerTest->{closure:Pest\Concerns\Testable::__callClosure():419}()
#4 /Users/azimsaibou/Desktop/php projects/sous-controle-docker/www/sous_controle/vendor/pestphp/pest/src/Concerns/Testable.php(419): Pest\Support\ExceptionTrace::ensure(Object(Closure))
#5 /Users/azimsaibou/Desktop/php projects/sous-controle-docker/www/sous_controle/vendor/pestphp/pest/src/Concerns/Testable.php(321): P\Tests\Unit\ExceptionHandlerTest->__callClosure(Object(Closure), Array)
#6 /Users/azimsaibou/Desktop/php projects/sous-controle-docker/www/sous_controle/vendor/pestphp/pest/src/Factories/TestCaseFactory.php(169) : eval()'d code(53): P\Tests\Unit\ExceptionHandlerTest->__runTest(Object(Closure))
#7 /Users/azimsaibou/Desktop/php projects/sous-controle-docker/www/sous_controle/vendor/phpunit/phpunit/src/Framework/TestCase.php(1235): P\Tests\Unit\ExceptionHandlerTest->__pest_evaluable_ExceptionHandler_sets_HTTP_status_code_404_when_PageNotFoundException_is_thrown()
#8 /Users/azimsaibou/Desktop/php projects/sous-controle-docker/www/sous_controle/vendor/phpunit/phpunit/src/Framework/TestCase.php(514): PHPUnit\Framework\TestCase->runTest()
#9 /Users/azimsaibou/Desktop/php projects/sous-controle-docker/www/sous_controle/vendor/phpunit/phpunit/src/Framework/TestRunner/TestRunner.php(87): PHPUnit\Framework\TestCase->runBare()
#10 /Users/azimsaibou/Desktop/php projects/sous-controle-docker/www/sous_controle/vendor/phpunit/phpunit/src/Framework/TestCase.php(361): PHPUnit\Framework\TestRunner->run(Object(P\Tests\Unit\ExceptionHandlerTest))
#11 /Users/azimsaibou/Desktop/php projects/sous-controle-docker/www/sous_controle/vendor/phpunit/phpunit/src/Framework/TestSuite.php(369): PHPUnit\Framework\TestCase->run()
#12 /Users/azimsaibou/Desktop/php projects/sous-controle-docker/www/sous_controle/vendor/phpunit/phpunit/src/Framework/TestSuite.php(369): PHPUnit\Framework\TestSuite->run()
#13 /Users/azimsaibou/Desktop/php projects/sous-controle-docker/www/sous_controle/vendor/phpunit/phpunit/src/Framework/TestSuite.php(369): PHPUnit\Framework\TestSuite->run()
#14 /Users/azimsaibou/Desktop/php projects/sous-controle-docker/www/sous_controle/vendor/phpunit/phpunit/src/TextUI/TestRunner.php(64): PHPUnit\Framework\TestSuite->run()
#15 /Users/azimsaibou/Desktop/php projects/sous-controle-docker/www/sous_controle/vendor/phpunit/phpunit/src/TextUI/Application.php(210): PHPUnit\TextUI\TestRunner->run(Object(PHPUnit\TextUI\Configuration\Configuration), Object(PHPUnit\Runner\ResultCache\DefaultResultCache), Object(PHPUnit\Framework\TestSuite))
#16 /Users/azimsaibou/Desktop/php projects/sous-controle-docker/www/sous_controle/vendor/pestphp/pest/src/Kernel.php(103): PHPUnit\TextUI\Application->run(Array)
#17 /Users/azimsaibou/Desktop/php projects/sous-controle-docker/www/sous_controle/vendor/pestphp/pest/bin/pest(184): Pest\Kernel->handle(Array, Array)
#18 /Users/azimsaibou/Desktop/php projects/sous-controle-docker/www/sous_controle/vendor/pestphp/pest/bin/pest(192): {closure:/Users/azimsaibou/Desktop/php projects/sous-controle-docker/www/sous_controle/vendor/pestphp/pest/bin/pest:18}()
#19 /Users/azimsaibou/Desktop/php projects/sous-controle-docker/www/sous_controle/vendor/bin/pest(119): include('/Users/azimsaib...')
#20 {main}

[2025-03-28 22:37:26] Exception: A Page Is Not Found 
in /Users/azimsaibou/Desktop/php projects/sous-controle-docker/www/sous_controle/tests/Unit/ExceptionHandlerTest.php 
on line 37
Trace: #0 /Users/azimsaibou/Desktop/php projects/sous-controle-docker/www/sous_controle/vendor/pestphp/pest/src/Factories/TestCaseMethodFactory.php(168): P\Tests\Unit\ExceptionHandlerTest->{closure:/Users/azimsaibou/Desktop/php projects/sous-controle-docker/www/sous_controle/tests/Unit/ExceptionHandlerTest.php:33}()
#1 [internal function]: P\Tests\Unit\ExceptionHandlerTest->{closure:Pest\Factories\TestCaseMethodFactory::getClosure():158}()
#2 /Users/azimsaibou/Desktop/php projects/sous-controle-docker/www/sous_controle/vendor/pestphp/pest/src/Concerns/Testable.php(419): call_user_func_array(Object(Closure), Array)
#3 /Users/azimsaibou/Desktop/php projects/sous-controle-docker/www/sous_controle/vendor/pestphp/pest/src/Support/ExceptionTrace.php(26): P\Tests\Unit\ExceptionHandlerTest->{closure:Pest\Concerns\Testable::__callClosure():419}()
#4 /Users/azimsaibou/Desktop/php projects/sous-controle-docker/www/sous_controle/vendor/pestphp/pest/src/Concerns/Testable.php(419): Pest\Support\ExceptionTrace::ensure(Object(Closure))
#5 /Users/azimsaibou/Desktop/php projects/sous-controle-docker/www/sous_controle/vendor/pestphp/pest/src/Concerns/Testable.php(321): P\Tests\Unit\ExceptionHandlerTest->__callClosure(Object(Closure), Array)
#6 /Users/azimsaibou/Desktop/php projects/sous-controle-docker/www/sous_controle/vendor/pestphp/pest/src/Factories/TestCaseFactory.php(169) : eval()'d code(35): P\Tests\Unit\ExceptionHandlerTest->__runTest(Object(Closure))
#7 /Users/azimsaibou/Desktop/php projects/sous-controle-docker/www/sous_controle/vendor/phpunit/phpunit/src/Framework/TestCase.php(1235): P\Tests\Unit\ExceptionHandlerTest->__pest_evaluable_it_print_a_generic_message_in_production_mode_when_a_page_not_found_exception_is_thrown()
#8 /Users/azimsaibou/Desktop/php projects/sous-controle-docker/www/sous_controle/vendor/phpunit/phpunit/src/Framework/TestCase.php(514): PHPUnit\Framework\TestCase->runTest()
#9 /Users/azimsaibou/Desktop/php projects/sous-controle-docker/www/sous_controle/vendor/phpunit/phpunit/src/Framework/TestRunner/TestRunner.php(87): PHPUnit\Framework\TestCase->runBare()
#10 /Users/azimsaibou/Desktop/php projects/sous-controle-docker/www/sous_controle/vendor/phpunit/phpunit/src/Framework/TestCase.php(361): PHPUnit\Framework\TestRunner->run(Object(P\Tests\Unit\ExceptionHandlerTest))
#11 /Users/azimsaibou/Desktop/php projects/sous-controle-docker/www/sous_controle/vendor/phpunit/phpunit/src/Framework/TestSuite.php(369): PHPUnit\Framework\TestCase->run()
#12 /Users/azimsaibou/Desktop/php projects/sous-controle-docker/www/sous_controle/vendor/phpunit/phpunit/src/Framework/TestSuite.php(369): PHPUnit\Framework\TestSuite->run()
#13 /Users/azimsaibou/Desktop/php projects/sous-controle-docker/www/sous_controle/vendor/phpunit/phpunit/src/Framework/TestSuite.php(369): PHPUnit\Framework\TestSuite->run()
#14 /Users/azimsaibou/Desktop/php projects/sous-controle-docker/www/sous_controle/vendor/phpunit/phpunit/src/TextUI/TestRunner.php(64): PHPUnit\Framework\TestSuite->run()
#15 /Users/azimsaibou/Desktop/php projects/sous-controle-docker/www/sous_controle/vendor/phpunit/phpunit/src/TextUI/Application.php(210): PHPUnit\TextUI\TestRunner->run(Object(PHPUnit\TextUI\Configuration\Configuration), Object(PHPUnit\Runner\ResultCache\DefaultResultCache), Object(PHPUnit\Framework\TestSuite))
#16 /Users/azimsaibou/Desktop/php projects/sous-controle-docker/www/sous_controle/vendor/pestphp/pest/src/Kernel.php(103): PHPUnit\TextUI\Application->run(Array)
#17 /Users/azimsaibou/Desktop/php projects/sous-controle-docker/www/sous_controle/vendor/pestphp/pest/bin/pest(184): Pest\Kernel->handle(Array, Array)
#18 /Users/azimsaibou/Desktop/php projects/sous-controle-docker/www/sous_controle/vendor/pestphp/pest/bin/pest(192): {closure:/Users/azimsaibou/Desktop/php projects/sous-controle-docker/www/sous_controle/vendor/pestphp/pest/bin/pest:18}()
#19 /Users/azimsaibou/Desktop/php projects/sous-controle-docker/www/sous_controle/vendor/bin/pest(119): include('/Users/azimsaib...')
#20 {main}

[2025-03-28 22:37:26] Exception: A Page Is Not Found 
in /Users/azimsaibou/Desktop/php projects/sous-controle-docker/www/sous_controle/tests/Unit/ExceptionHandlerTest.php 
on line 47
Trace: #0 /Users/azimsaibou/Desktop/php projects/sous-controle-docker/www/sous_controle/vendor/pestphp/pest/src/Factories/TestCaseMethodFactory.php(168): P\Tests\Unit\ExceptionHandlerTest->{closure:/Users/azimsaibou/Desktop/php projects/sous-controle-docker/www/sous_controle/tests/Unit/ExceptionHandlerTest.php:43}()
#1 [internal function]: P\Tests\Unit\ExceptionHandlerTest->{closure:Pest\Factories\TestCaseMethodFactory::getClosure():158}()
#2 /Users/azimsaibou/Desktop/php projects/sous-controle-docker/www/sous_controle/vendor/pestphp/pest/src/Concerns/Testable.php(419): call_user_func_array(Object(Closure), Array)
#3 /Users/azimsaibou/Desktop/php projects/sous-controle-docker/www/sous_controle/vendor/pestphp/pest/src/Support/ExceptionTrace.php(26): P\Tests\Unit\ExceptionHandlerTest->{closure:Pest\Concerns\Testable::__callClosure():419}()
#4 /Users/azimsaibou/Desktop/php projects/sous-controle-docker/www/sous_controle/vendor/pestphp/pest/src/Concerns/Testable.php(419): Pest\Support\ExceptionTrace::ensure(Object(Closure))
#5 /Users/azimsaibou/Desktop/php projects/sous-controle-docker/www/sous_controle/vendor/pestphp/pest/src/Concerns/Testable.php(321): P\Tests\Unit\ExceptionHandlerTest->__callClosure(Object(Closure), Array)
#6 /Users/azimsaibou/Desktop/php projects/sous-controle-docker/www/sous_controle/vendor/pestphp/pest/src/Factories/TestCaseFactory.php(169) : eval()'d code(44): P\Tests\Unit\ExceptionHandlerTest->__runTest(Object(Closure))
#7 /Users/azimsaibou/Desktop/php projects/sous-controle-docker/www/sous_controle/vendor/phpunit/phpunit/src/Framework/TestCase.php(1235): P\Tests\Unit\ExceptionHandlerTest->__pest_evaluable_it_print_a_generic_message_in_production_mode_when_other_exception_is_thrown()
#8 /Users/azimsaibou/Desktop/php projects/sous-controle-docker/www/sous_controle/vendor/phpunit/phpunit/src/Framework/TestCase.php(514): PHPUnit\Framework\TestCase->runTest()
#9 /Users/azimsaibou/Desktop/php projects/sous-controle-docker/www/sous_controle/vendor/phpunit/phpunit/src/Framework/TestRunner/TestRunner.php(87): PHPUnit\Framework\TestCase->runBare()
#10 /Users/azimsaibou/Desktop/php projects/sous-controle-docker/www/sous_controle/vendor/phpunit/phpunit/src/Framework/TestCase.php(361): PHPUnit\Framework\TestRunner->run(Object(P\Tests\Unit\ExceptionHandlerTest))
#11 /Users/azimsaibou/Desktop/php projects/sous-controle-docker/www/sous_controle/vendor/phpunit/phpunit/src/Framework/TestSuite.php(369): PHPUnit\Framework\TestCase->run()
#12 /Users/azimsaibou/Desktop/php projects/sous-controle-docker/www/sous_controle/vendor/phpunit/phpunit/src/Framework/TestSuite.php(369): PHPUnit\Framework\TestSuite->run()
#13 /Users/azimsaibou/Desktop/php projects/sous-controle-docker/www/sous_controle/vendor/phpunit/phpunit/src/Framework/TestSuite.php(369): PHPUnit\Framework\TestSuite->run()
#14 /Users/azimsaibou/Desktop/php projects/sous-controle-docker/www/sous_controle/vendor/phpunit/phpunit/src/TextUI/TestRunner.php(64): PHPUnit\Framework\TestSuite->run()
#15 /Users/azimsaibou/Desktop/php projects/sous-controle-docker/www/sous_controle/vendor/phpunit/phpunit/src/TextUI/Application.php(210): PHPUnit\TextUI\TestRunner->run(Object(PHPUnit\TextUI\Configuration\Configuration), Object(PHPUnit\Runner\ResultCache\DefaultResultCache), Object(PHPUnit\Framework\TestSuite))
#16 /Users/azimsaibou/Desktop/php projects/sous-controle-docker/www/sous_controle/vendor/pestphp/pest/src/Kernel.php(103): PHPUnit\TextUI\Application->run(Array)
#17 /Users/azimsaibou/Desktop/php projects/sous-controle-docker/www/sous_controle/vendor/pestphp/pest/bin/pest(184): Pest\Kernel->handle(Array, Array)
#18 /Users/azimsaibou/Desktop/php projects/sous-controle-docker/www/sous_controle/vendor/pestphp/pest/bin/pest(192): {closure:/Users/azimsaibou/Desktop/php projects/sous-controle-docker/www/sous_controle/vendor/pestphp/pest/bin/pest:18}()
#19 /Users/azimsaibou/Desktop/php projects/sous-controle-docker/www/sous_controle/vendor/bin/pest(119): include('/Users/azimsaib...')
#20 {main}

[2025-03-28 22:37:26] Exception: Test error 
in /Users/azimsaibou/Desktop/php projects/sous-controle-docker/www/sous_controle/tests/Unit/ExceptionHandlerTest.php 
on line 60
Trace: #0 /Users/azimsaibou/Desktop/php projects/sous-controle-docker/www/sous_controle/vendor/pestphp/pest/src/Factories/TestCaseMethodFactory.php(168): P\Tests\Unit\ExceptionHandlerTest->{closure:/Users/azimsaibou/Desktop/php projects/sous-controle-docker/www/sous_controle/tests/Unit/ExceptionHandlerTest.php:57}()
#1 [internal function]: P\Tests\Unit\ExceptionHandlerTest->{closure:Pest\Factories\TestCaseMethodFactory::getClosure():158}()
#2 /Users/azimsaibou/Desktop/php projects/sous-controle-docker/www/sous_controle/vendor/pestphp/pest/src/Concerns/Testable.php(419): call_user_func_array(Object(Closure), Array)
#3 /Users/azimsaibou/Desktop/php projects/sous-controle-docker/www/sous_controle/vendor/pestphp/pest/src/Support/ExceptionTrace.php(26): P\Tests\Unit\ExceptionHandlerTest->{closure:Pest\Concerns\Testable::__callClosure():419}()
#4 /Users/azimsaibou/Desktop/php projects/sous-controle-docker/www/sous_controle/vendor/pestphp/pest/src/Concerns/Testable.php(419): Pest\Support\ExceptionTrace::ensure(Object(Closure))
#5 /Users/azimsaibou/Desktop/php projects/sous-controle-docker/www/sous_controle/vendor/pestphp/pest/src/Concerns/Testable.php(321): P\Tests\Unit\ExceptionHandlerTest->__callClosure(Object(Closure), Array)
#6 /Users/azimsaibou/Desktop/php projects/sous-controle-docker/www/sous_controle/vendor/pestphp/pest/src/Factories/TestCaseFactory.php(169) : eval()'d code(53): P\Tests\Unit\ExceptionHandlerTest->__runTest(Object(Closure))
#7 /Users/azimsaibou/Desktop/php projects/sous-controle-docker/www/sous_controle/vendor/phpunit/phpunit/src/Framework/TestCase.php(1235): P\Tests\Unit\ExceptionHandlerTest->__pest_evaluable_ExceptionHandler_sets_HTTP_status_code_404_when_PageNotFoundException_is_thrown()
#8 /Users/azimsaibou/Desktop/php projects/sous-controle-docker/www/sous_controle/vendor/phpunit/phpunit/src/Framework/TestCase.php(514): PHPUnit\Framework\TestCase->runTest()
#9 /Users/azimsaibou/Desktop/php projects/sous-controle-docker/www/sous_controle/vendor/phpunit/phpunit/src/Framework/TestRunner/TestRunner.php(87): PHPUnit\Framework\TestCase->runBare()
#10 /Users/azimsaibou/Desktop/php projects/sous-controle-docker/www/sous_controle/vendor/phpunit/phpunit/src/Framework/TestCase.php(361): PHPUnit\Framework\TestRunner->run(Object(P\Tests\Unit\ExceptionHandlerTest))
#11 /Users/azimsaibou/Desktop/php projects/sous-controle-docker/www/sous_controle/vendor/phpunit/phpunit/src/Framework/TestSuite.php(369): PHPUnit\Framework\TestCase->run()
#12 /Users/azimsaibou/Desktop/php projects/sous-controle-docker/www/sous_controle/vendor/phpunit/phpunit/src/Framework/TestSuite.php(369): PHPUnit\Framework\TestSuite->run()
#13 /Users/azimsaibou/Desktop/php projects/sous-controle-docker/www/sous_controle/vendor/phpunit/phpunit/src/Framework/TestSuite.php(369): PHPUnit\Framework\TestSuite->run()
#14 /Users/azimsaibou/Desktop/php projects/sous-controle-docker/www/sous_controle/vendor/phpunit/phpunit/src/TextUI/TestRunner.php(64): PHPUnit\Framework\TestSuite->run()
#15 /Users/azimsaibou/Desktop/php projects/sous-controle-docker/www/sous_controle/vendor/phpunit/phpunit/src/TextUI/Application.php(210): PHPUnit\TextUI\TestRunner->run(Object(PHPUnit\TextUI\Configuration\Configuration), Object(PHPUnit\Runner\ResultCache\DefaultResultCache), Object(PHPUnit\Framework\TestSuite))
#16 /Users/azimsaibou/Desktop/php projects/sous-controle-docker/www/sous_controle/vendor/pestphp/pest/src/Kernel.php(103): PHPUnit\TextUI\Application->run(Array)
#17 /Users/azimsaibou/Desktop/php projects/sous-controle-docker/www/sous_controle/vendor/pestphp/pest/bin/pest(184): Pest\Kernel->handle(Array, Array)
#18 /Users/azimsaibou/Desktop/php projects/sous-controle-docker/www/sous_controle/vendor/pestphp/pest/bin/pest(192): {closure:/Users/azimsaibou/Desktop/php projects/sous-controle-docker/www/sous_controle/vendor/pestphp/pest/bin/pest:18}()
#19 /Users/azimsaibou/Desktop/php projects/sous-controle-docker/www/sous_controle/vendor/bin/pest(119): include('/Users/azimsaib...')
#20 {main}

[2025-03-28 22:38:41] Exception: A Page Is Not Found 
in /Users/azimsaibou/Desktop/php projects/sous-controle-docker/www/sous_controle/tests/Unit/ExceptionHandlerTest.php 
on line 37
Trace: #0 /Users/azimsaibou/Desktop/php projects/sous-controle-docker/www/sous_controle/vendor/pestphp/pest/src/Factories/TestCaseMethodFactory.php(168): P\Tests\Unit\ExceptionHandlerTest->{closure:/Users/azimsaibou/Desktop/php projects/sous-controle-docker/www/sous_controle/tests/Unit/ExceptionHandlerTest.php:33}()
#1 [internal function]: P\Tests\Unit\ExceptionHandlerTest->{closure:Pest\Factories\TestCaseMethodFactory::getClosure():158}()
#2 /Users/azimsaibou/Desktop/php projects/sous-controle-docker/www/sous_controle/vendor/pestphp/pest/src/Concerns/Testable.php(419): call_user_func_array(Object(Closure), Array)
#3 /Users/azimsaibou/Desktop/php projects/sous-controle-docker/www/sous_controle/vendor/pestphp/pest/src/Support/ExceptionTrace.php(26): P\Tests\Unit\ExceptionHandlerTest->{closure:Pest\Concerns\Testable::__callClosure():419}()
#4 /Users/azimsaibou/Desktop/php projects/sous-controle-docker/www/sous_controle/vendor/pestphp/pest/src/Concerns/Testable.php(419): Pest\Support\ExceptionTrace::ensure(Object(Closure))
#5 /Users/azimsaibou/Desktop/php projects/sous-controle-docker/www/sous_controle/vendor/pestphp/pest/src/Concerns/Testable.php(321): P\Tests\Unit\ExceptionHandlerTest->__callClosure(Object(Closure), Array)
#6 /Users/azimsaibou/Desktop/php projects/sous-controle-docker/www/sous_controle/vendor/pestphp/pest/src/Factories/TestCaseFactory.php(169) : eval()'d code(35): P\Tests\Unit\ExceptionHandlerTest->__runTest(Object(Closure))
#7 /Users/azimsaibou/Desktop/php projects/sous-controle-docker/www/sous_controle/vendor/phpunit/phpunit/src/Framework/TestCase.php(1235): P\Tests\Unit\ExceptionHandlerTest->__pest_evaluable_it_print_a_generic_message_in_production_mode_when_a_page_not_found_exception_is_thrown()
#8 /Users/azimsaibou/Desktop/php projects/sous-controle-docker/www/sous_controle/vendor/phpunit/phpunit/src/Framework/TestCase.php(514): PHPUnit\Framework\TestCase->runTest()
#9 /Users/azimsaibou/Desktop/php projects/sous-controle-docker/www/sous_controle/vendor/phpunit/phpunit/src/Framework/TestRunner/TestRunner.php(87): PHPUnit\Framework\TestCase->runBare()
#10 /Users/azimsaibou/Desktop/php projects/sous-controle-docker/www/sous_controle/vendor/phpunit/phpunit/src/Framework/TestCase.php(361): PHPUnit\Framework\TestRunner->run(Object(P\Tests\Unit\ExceptionHandlerTest))
#11 /Users/azimsaibou/Desktop/php projects/sous-controle-docker/www/sous_controle/vendor/phpunit/phpunit/src/Framework/TestSuite.php(369): PHPUnit\Framework\TestCase->run()
#12 /Users/azimsaibou/Desktop/php projects/sous-controle-docker/www/sous_controle/vendor/phpunit/phpunit/src/Framework/TestSuite.php(369): PHPUnit\Framework\TestSuite->run()
#13 /Users/azimsaibou/Desktop/php projects/sous-controle-docker/www/sous_controle/vendor/phpunit/phpunit/src/Framework/TestSuite.php(369): PHPUnit\Framework\TestSuite->run()
#14 /Users/azimsaibou/Desktop/php projects/sous-controle-docker/www/sous_controle/vendor/phpunit/phpunit/src/TextUI/TestRunner.php(64): PHPUnit\Framework\TestSuite->run()
#15 /Users/azimsaibou/Desktop/php projects/sous-controle-docker/www/sous_controle/vendor/phpunit/phpunit/src/TextUI/Application.php(210): PHPUnit\TextUI\TestRunner->run(Object(PHPUnit\TextUI\Configuration\Configuration), Object(PHPUnit\Runner\ResultCache\DefaultResultCache), Object(PHPUnit\Framework\TestSuite))
#16 /Users/azimsaibou/Desktop/php projects/sous-controle-docker/www/sous_controle/vendor/pestphp/pest/src/Kernel.php(103): PHPUnit\TextUI\Application->run(Array)
#17 /Users/azimsaibou/Desktop/php projects/sous-controle-docker/www/sous_controle/vendor/pestphp/pest/bin/pest(184): Pest\Kernel->handle(Array, Array)
#18 /Users/azimsaibou/Desktop/php projects/sous-controle-docker/www/sous_controle/vendor/pestphp/pest/bin/pest(192): {closure:/Users/azimsaibou/Desktop/php projects/sous-controle-docker/www/sous_controle/vendor/pestphp/pest/bin/pest:18}()
#19 /Users/azimsaibou/Desktop/php projects/sous-controle-docker/www/sous_controle/vendor/bin/pest(119): include('/Users/azimsaib...')
#20 {main}

[2025-03-28 22:38:41] Exception: A Page Is Not Found 
in /Users/azimsaibou/Desktop/php projects/sous-controle-docker/www/sous_controle/tests/Unit/ExceptionHandlerTest.php 
on line 47
Trace: #0 /Users/azimsaibou/Desktop/php projects/sous-controle-docker/www/sous_controle/vendor/pestphp/pest/src/Factories/TestCaseMethodFactory.php(168): P\Tests\Unit\ExceptionHandlerTest->{closure:/Users/azimsaibou/Desktop/php projects/sous-controle-docker/www/sous_controle/tests/Unit/ExceptionHandlerTest.php:43}()
#1 [internal function]: P\Tests\Unit\ExceptionHandlerTest->{closure:Pest\Factories\TestCaseMethodFactory::getClosure():158}()
#2 /Users/azimsaibou/Desktop/php projects/sous-controle-docker/www/sous_controle/vendor/pestphp/pest/src/Concerns/Testable.php(419): call_user_func_array(Object(Closure), Array)
#3 /Users/azimsaibou/Desktop/php projects/sous-controle-docker/www/sous_controle/vendor/pestphp/pest/src/Support/ExceptionTrace.php(26): P\Tests\Unit\ExceptionHandlerTest->{closure:Pest\Concerns\Testable::__callClosure():419}()
#4 /Users/azimsaibou/Desktop/php projects/sous-controle-docker/www/sous_controle/vendor/pestphp/pest/src/Concerns/Testable.php(419): Pest\Support\ExceptionTrace::ensure(Object(Closure))
#5 /Users/azimsaibou/Desktop/php projects/sous-controle-docker/www/sous_controle/vendor/pestphp/pest/src/Concerns/Testable.php(321): P\Tests\Unit\ExceptionHandlerTest->__callClosure(Object(Closure), Array)
#6 /Users/azimsaibou/Desktop/php projects/sous-controle-docker/www/sous_controle/vendor/pestphp/pest/src/Factories/TestCaseFactory.php(169) : eval()'d code(44): P\Tests\Unit\ExceptionHandlerTest->__runTest(Object(Closure))
#7 /Users/azimsaibou/Desktop/php projects/sous-controle-docker/www/sous_controle/vendor/phpunit/phpunit/src/Framework/TestCase.php(1235): P\Tests\Unit\ExceptionHandlerTest->__pest_evaluable_it_print_a_generic_message_in_production_mode_when_other_exception_is_thrown()
#8 /Users/azimsaibou/Desktop/php projects/sous-controle-docker/www/sous_controle/vendor/phpunit/phpunit/src/Framework/TestCase.php(514): PHPUnit\Framework\TestCase->runTest()
#9 /Users/azimsaibou/Desktop/php projects/sous-controle-docker/www/sous_controle/vendor/phpunit/phpunit/src/Framework/TestRunner/TestRunner.php(87): PHPUnit\Framework\TestCase->runBare()
#10 /Users/azimsaibou/Desktop/php projects/sous-controle-docker/www/sous_controle/vendor/phpunit/phpunit/src/Framework/TestCase.php(361): PHPUnit\Framework\TestRunner->run(Object(P\Tests\Unit\ExceptionHandlerTest))
#11 /Users/azimsaibou/Desktop/php projects/sous-controle-docker/www/sous_controle/vendor/phpunit/phpunit/src/Framework/TestSuite.php(369): PHPUnit\Framework\TestCase->run()
#12 /Users/azimsaibou/Desktop/php projects/sous-controle-docker/www/sous_controle/vendor/phpunit/phpunit/src/Framework/TestSuite.php(369): PHPUnit\Framework\TestSuite->run()
#13 /Users/azimsaibou/Desktop/php projects/sous-controle-docker/www/sous_controle/vendor/phpunit/phpunit/src/Framework/TestSuite.php(369): PHPUnit\Framework\TestSuite->run()
#14 /Users/azimsaibou/Desktop/php projects/sous-controle-docker/www/sous_controle/vendor/phpunit/phpunit/src/TextUI/TestRunner.php(64): PHPUnit\Framework\TestSuite->run()
#15 /Users/azimsaibou/Desktop/php projects/sous-controle-docker/www/sous_controle/vendor/phpunit/phpunit/src/TextUI/Application.php(210): PHPUnit\TextUI\TestRunner->run(Object(PHPUnit\TextUI\Configuration\Configuration), Object(PHPUnit\Runner\ResultCache\DefaultResultCache), Object(PHPUnit\Framework\TestSuite))
#16 /Users/azimsaibou/Desktop/php projects/sous-controle-docker/www/sous_controle/vendor/pestphp/pest/src/Kernel.php(103): PHPUnit\TextUI\Application->run(Array)
#17 /Users/azimsaibou/Desktop/php projects/sous-controle-docker/www/sous_controle/vendor/pestphp/pest/bin/pest(184): Pest\Kernel->handle(Array, Array)
#18 /Users/azimsaibou/Desktop/php projects/sous-controle-docker/www/sous_controle/vendor/pestphp/pest/bin/pest(192): {closure:/Users/azimsaibou/Desktop/php projects/sous-controle-docker/www/sous_controle/vendor/pestphp/pest/bin/pest:18}()
#19 /Users/azimsaibou/Desktop/php projects/sous-controle-docker/www/sous_controle/vendor/bin/pest(119): include('/Users/azimsaib...')
#20 {main}

[2025-03-28 22:38:43] Exception: A Page Is Not Found 
in /Users/azimsaibou/Desktop/php projects/sous-controle-docker/www/sous_controle/tests/Unit/ExceptionHandlerTest.php 
on line 37
Trace: #0 /Users/azimsaibou/Desktop/php projects/sous-controle-docker/www/sous_controle/vendor/pestphp/pest/src/Factories/TestCaseMethodFactory.php(168): P\Tests\Unit\ExceptionHandlerTest->{closure:/Users/azimsaibou/Desktop/php projects/sous-controle-docker/www/sous_controle/tests/Unit/ExceptionHandlerTest.php:33}()
#1 [internal function]: P\Tests\Unit\ExceptionHandlerTest->{closure:Pest\Factories\TestCaseMethodFactory::getClosure():158}()
#2 /Users/azimsaibou/Desktop/php projects/sous-controle-docker/www/sous_controle/vendor/pestphp/pest/src/Concerns/Testable.php(419): call_user_func_array(Object(Closure), Array)
#3 /Users/azimsaibou/Desktop/php projects/sous-controle-docker/www/sous_controle/vendor/pestphp/pest/src/Support/ExceptionTrace.php(26): P\Tests\Unit\ExceptionHandlerTest->{closure:Pest\Concerns\Testable::__callClosure():419}()
#4 /Users/azimsaibou/Desktop/php projects/sous-controle-docker/www/sous_controle/vendor/pestphp/pest/src/Concerns/Testable.php(419): Pest\Support\ExceptionTrace::ensure(Object(Closure))
#5 /Users/azimsaibou/Desktop/php projects/sous-controle-docker/www/sous_controle/vendor/pestphp/pest/src/Concerns/Testable.php(321): P\Tests\Unit\ExceptionHandlerTest->__callClosure(Object(Closure), Array)
#6 /Users/azimsaibou/Desktop/php projects/sous-controle-docker/www/sous_controle/vendor/pestphp/pest/src/Factories/TestCaseFactory.php(169) : eval()'d code(35): P\Tests\Unit\ExceptionHandlerTest->__runTest(Object(Closure))
#7 /Users/azimsaibou/Desktop/php projects/sous-controle-docker/www/sous_controle/vendor/phpunit/phpunit/src/Framework/TestCase.php(1235): P\Tests\Unit\ExceptionHandlerTest->__pest_evaluable_it_print_a_generic_message_in_production_mode_when_a_page_not_found_exception_is_thrown()
#8 /Users/azimsaibou/Desktop/php projects/sous-controle-docker/www/sous_controle/vendor/phpunit/phpunit/src/Framework/TestCase.php(514): PHPUnit\Framework\TestCase->runTest()
#9 /Users/azimsaibou/Desktop/php projects/sous-controle-docker/www/sous_controle/vendor/phpunit/phpunit/src/Framework/TestRunner/TestRunner.php(87): PHPUnit\Framework\TestCase->runBare()
#10 /Users/azimsaibou/Desktop/php projects/sous-controle-docker/www/sous_controle/vendor/phpunit/phpunit/src/Framework/TestCase.php(361): PHPUnit\Framework\TestRunner->run(Object(P\Tests\Unit\ExceptionHandlerTest))
#11 /Users/azimsaibou/Desktop/php projects/sous-controle-docker/www/sous_controle/vendor/phpunit/phpunit/src/Framework/TestSuite.php(369): PHPUnit\Framework\TestCase->run()
#12 /Users/azimsaibou/Desktop/php projects/sous-controle-docker/www/sous_controle/vendor/phpunit/phpunit/src/Framework/TestSuite.php(369): PHPUnit\Framework\TestSuite->run()
#13 /Users/azimsaibou/Desktop/php projects/sous-controle-docker/www/sous_controle/vendor/phpunit/phpunit/src/Framework/TestSuite.php(369): PHPUnit\Framework\TestSuite->run()
#14 /Users/azimsaibou/Desktop/php projects/sous-controle-docker/www/sous_controle/vendor/phpunit/phpunit/src/TextUI/TestRunner.php(64): PHPUnit\Framework\TestSuite->run()
#15 /Users/azimsaibou/Desktop/php projects/sous-controle-docker/www/sous_controle/vendor/phpunit/phpunit/src/TextUI/Application.php(210): PHPUnit\TextUI\TestRunner->run(Object(PHPUnit\TextUI\Configuration\Configuration), Object(PHPUnit\Runner\ResultCache\DefaultResultCache), Object(PHPUnit\Framework\TestSuite))
#16 /Users/azimsaibou/Desktop/php projects/sous-controle-docker/www/sous_controle/vendor/pestphp/pest/src/Kernel.php(103): PHPUnit\TextUI\Application->run(Array)
#17 /Users/azimsaibou/Desktop/php projects/sous-controle-docker/www/sous_controle/vendor/pestphp/pest/bin/pest(184): Pest\Kernel->handle(Array, Array)
#18 /Users/azimsaibou/Desktop/php projects/sous-controle-docker/www/sous_controle/vendor/pestphp/pest/bin/pest(192): {closure:/Users/azimsaibou/Desktop/php projects/sous-controle-docker/www/sous_controle/vendor/pestphp/pest/bin/pest:18}()
#19 /Users/azimsaibou/Desktop/php projects/sous-controle-docker/www/sous_controle/vendor/bin/pest(119): include('/Users/azimsaib...')
#20 {main}

[2025-03-28 22:38:43] Exception: A Page Is Not Found 
in /Users/azimsaibou/Desktop/php projects/sous-controle-docker/www/sous_controle/tests/Unit/ExceptionHandlerTest.php 
on line 47
Trace: #0 /Users/azimsaibou/Desktop/php projects/sous-controle-docker/www/sous_controle/vendor/pestphp/pest/src/Factories/TestCaseMethodFactory.php(168): P\Tests\Unit\ExceptionHandlerTest->{closure:/Users/azimsaibou/Desktop/php projects/sous-controle-docker/www/sous_controle/tests/Unit/ExceptionHandlerTest.php:43}()
#1 [internal function]: P\Tests\Unit\ExceptionHandlerTest->{closure:Pest\Factories\TestCaseMethodFactory::getClosure():158}()
#2 /Users/azimsaibou/Desktop/php projects/sous-controle-docker/www/sous_controle/vendor/pestphp/pest/src/Concerns/Testable.php(419): call_user_func_array(Object(Closure), Array)
#3 /Users/azimsaibou/Desktop/php projects/sous-controle-docker/www/sous_controle/vendor/pestphp/pest/src/Support/ExceptionTrace.php(26): P\Tests\Unit\ExceptionHandlerTest->{closure:Pest\Concerns\Testable::__callClosure():419}()
#4 /Users/azimsaibou/Desktop/php projects/sous-controle-docker/www/sous_controle/vendor/pestphp/pest/src/Concerns/Testable.php(419): Pest\Support\ExceptionTrace::ensure(Object(Closure))
#5 /Users/azimsaibou/Desktop/php projects/sous-controle-docker/www/sous_controle/vendor/pestphp/pest/src/Concerns/Testable.php(321): P\Tests\Unit\ExceptionHandlerTest->__callClosure(Object(Closure), Array)
#6 /Users/azimsaibou/Desktop/php projects/sous-controle-docker/www/sous_controle/vendor/pestphp/pest/src/Factories/TestCaseFactory.php(169) : eval()'d code(44): P\Tests\Unit\ExceptionHandlerTest->__runTest(Object(Closure))
#7 /Users/azimsaibou/Desktop/php projects/sous-controle-docker/www/sous_controle/vendor/phpunit/phpunit/src/Framework/TestCase.php(1235): P\Tests\Unit\ExceptionHandlerTest->__pest_evaluable_it_print_a_generic_message_in_production_mode_when_other_exception_is_thrown()
#8 /Users/azimsaibou/Desktop/php projects/sous-controle-docker/www/sous_controle/vendor/phpunit/phpunit/src/Framework/TestCase.php(514): PHPUnit\Framework\TestCase->runTest()
#9 /Users/azimsaibou/Desktop/php projects/sous-controle-docker/www/sous_controle/vendor/phpunit/phpunit/src/Framework/TestRunner/TestRunner.php(87): PHPUnit\Framework\TestCase->runBare()
#10 /Users/azimsaibou/Desktop/php projects/sous-controle-docker/www/sous_controle/vendor/phpunit/phpunit/src/Framework/TestCase.php(361): PHPUnit\Framework\TestRunner->run(Object(P\Tests\Unit\ExceptionHandlerTest))
#11 /Users/azimsaibou/Desktop/php projects/sous-controle-docker/www/sous_controle/vendor/phpunit/phpunit/src/Framework/TestSuite.php(369): PHPUnit\Framework\TestCase->run()
#12 /Users/azimsaibou/Desktop/php projects/sous-controle-docker/www/sous_controle/vendor/phpunit/phpunit/src/Framework/TestSuite.php(369): PHPUnit\Framework\TestSuite->run()
#13 /Users/azimsaibou/Desktop/php projects/sous-controle-docker/www/sous_controle/vendor/phpunit/phpunit/src/Framework/TestSuite.php(369): PHPUnit\Framework\TestSuite->run()
#14 /Users/azimsaibou/Desktop/php projects/sous-controle-docker/www/sous_controle/vendor/phpunit/phpunit/src/TextUI/TestRunner.php(64): PHPUnit\Framework\TestSuite->run()
#15 /Users/azimsaibou/Desktop/php projects/sous-controle-docker/www/sous_controle/vendor/phpunit/phpunit/src/TextUI/Application.php(210): PHPUnit\TextUI\TestRunner->run(Object(PHPUnit\TextUI\Configuration\Configuration), Object(PHPUnit\Runner\ResultCache\DefaultResultCache), Object(PHPUnit\Framework\TestSuite))
#16 /Users/azimsaibou/Desktop/php projects/sous-controle-docker/www/sous_controle/vendor/pestphp/pest/src/Kernel.php(103): PHPUnit\TextUI\Application->run(Array)
#17 /Users/azimsaibou/Desktop/php projects/sous-controle-docker/www/sous_controle/vendor/pestphp/pest/bin/pest(184): Pest\Kernel->handle(Array, Array)
#18 /Users/azimsaibou/Desktop/php projects/sous-controle-docker/www/sous_controle/vendor/pestphp/pest/bin/pest(192): {closure:/Users/azimsaibou/Desktop/php projects/sous-controle-docker/www/sous_controle/vendor/pestphp/pest/bin/pest:18}()
#19 /Users/azimsaibou/Desktop/php projects/sous-controle-docker/www/sous_controle/vendor/bin/pest(119): include('/Users/azimsaib...')
#20 {main}

[2025-03-28 23:04:56] Exception: A Page Is Not Found 
in /Users/azimsaibou/Desktop/php projects/sous-controle-docker/www/sous_controle/tests/Unit/ExceptionHandlerTest.php 
on line 49
Trace: #0 /Users/azimsaibou/Desktop/php projects/sous-controle-docker/www/sous_controle/vendor/pestphp/pest/src/Factories/TestCaseMethodFactory.php(168): P\Tests\Unit\ExceptionHandlerTest->{closure:/Users/azimsaibou/Desktop/php projects/sous-controle-docker/www/sous_controle/tests/Unit/ExceptionHandlerTest.php:42}()
#1 [internal function]: P\Tests\Unit\ExceptionHandlerTest->{closure:Pest\Factories\TestCaseMethodFactory::getClosure():158}()
#2 /Users/azimsaibou/Desktop/php projects/sous-controle-docker/www/sous_controle/vendor/pestphp/pest/src/Concerns/Testable.php(419): call_user_func_array(Object(Closure), Array)
#3 /Users/azimsaibou/Desktop/php projects/sous-controle-docker/www/sous_controle/vendor/pestphp/pest/src/Support/ExceptionTrace.php(26): P\Tests\Unit\ExceptionHandlerTest->{closure:Pest\Concerns\Testable::__callClosure():419}()
#4 /Users/azimsaibou/Desktop/php projects/sous-controle-docker/www/sous_controle/vendor/pestphp/pest/src/Concerns/Testable.php(419): Pest\Support\ExceptionTrace::ensure(Object(Closure))
#5 /Users/azimsaibou/Desktop/php projects/sous-controle-docker/www/sous_controle/vendor/pestphp/pest/src/Concerns/Testable.php(321): P\Tests\Unit\ExceptionHandlerTest->__callClosure(Object(Closure), Array)
#6 /Users/azimsaibou/Desktop/php projects/sous-controle-docker/www/sous_controle/vendor/pestphp/pest/src/Factories/TestCaseFactory.php(169) : eval()'d code(35): P\Tests\Unit\ExceptionHandlerTest->__runTest(Object(Closure))
#7 /Users/azimsaibou/Desktop/php projects/sous-controle-docker/www/sous_controle/vendor/phpunit/phpunit/src/Framework/TestCase.php(1235): P\Tests\Unit\ExceptionHandlerTest->__pest_evaluable_it_print_a_generic_message_in_production_mode_when_a_page_not_found_exception_is_thrown()
#8 /Users/azimsaibou/Desktop/php projects/sous-controle-docker/www/sous_controle/vendor/phpunit/phpunit/src/Framework/TestCase.php(514): PHPUnit\Framework\TestCase->runTest()
#9 /Users/azimsaibou/Desktop/php projects/sous-controle-docker/www/sous_controle/vendor/phpunit/phpunit/src/Framework/TestRunner/TestRunner.php(87): PHPUnit\Framework\TestCase->runBare()
#10 /Users/azimsaibou/Desktop/php projects/sous-controle-docker/www/sous_controle/vendor/phpunit/phpunit/src/Framework/TestCase.php(361): PHPUnit\Framework\TestRunner->run(Object(P\Tests\Unit\ExceptionHandlerTest))
#11 /Users/azimsaibou/Desktop/php projects/sous-controle-docker/www/sous_controle/vendor/phpunit/phpunit/src/Framework/TestSuite.php(369): PHPUnit\Framework\TestCase->run()
#12 /Users/azimsaibou/Desktop/php projects/sous-controle-docker/www/sous_controle/vendor/phpunit/phpunit/src/Framework/TestSuite.php(369): PHPUnit\Framework\TestSuite->run()
#13 /Users/azimsaibou/Desktop/php projects/sous-controle-docker/www/sous_controle/vendor/phpunit/phpunit/src/Framework/TestSuite.php(369): PHPUnit\Framework\TestSuite->run()
#14 /Users/azimsaibou/Desktop/php projects/sous-controle-docker/www/sous_controle/vendor/phpunit/phpunit/src/TextUI/TestRunner.php(64): PHPUnit\Framework\TestSuite->run()
#15 /Users/azimsaibou/Desktop/php projects/sous-controle-docker/www/sous_controle/vendor/phpunit/phpunit/src/TextUI/Application.php(210): PHPUnit\TextUI\TestRunner->run(Object(PHPUnit\TextUI\Configuration\Configuration), Object(PHPUnit\Runner\ResultCache\DefaultResultCache), Object(PHPUnit\Framework\TestSuite))
#16 /Users/azimsaibou/Desktop/php projects/sous-controle-docker/www/sous_controle/vendor/pestphp/pest/src/Kernel.php(103): PHPUnit\TextUI\Application->run(Array)
#17 /Users/azimsaibou/Desktop/php projects/sous-controle-docker/www/sous_controle/vendor/pestphp/pest/bin/pest(184): Pest\Kernel->handle(Array, Array)
#18 /Users/azimsaibou/Desktop/php projects/sous-controle-docker/www/sous_controle/vendor/pestphp/pest/bin/pest(192): {closure:/Users/azimsaibou/Desktop/php projects/sous-controle-docker/www/sous_controle/vendor/pestphp/pest/bin/pest:18}()
#19 /Users/azimsaibou/Desktop/php projects/sous-controle-docker/www/sous_controle/vendor/bin/pest(119): include('/Users/azimsaib...')
#20 {main}

[2025-03-28 23:05:44] Exception: A Page Is Not Found 
in /Users/azimsaibou/Desktop/php projects/sous-controle-docker/www/sous_controle/tests/Unit/ExceptionHandlerTest.php 
on line 49
Trace: #0 /Users/azimsaibou/Desktop/php projects/sous-controle-docker/www/sous_controle/vendor/pestphp/pest/src/Factories/TestCaseMethodFactory.php(168): P\Tests\Unit\ExceptionHandlerTest->{closure:/Users/azimsaibou/Desktop/php projects/sous-controle-docker/www/sous_controle/tests/Unit/ExceptionHandlerTest.php:42}()
#1 [internal function]: P\Tests\Unit\ExceptionHandlerTest->{closure:Pest\Factories\TestCaseMethodFactory::getClosure():158}()
#2 /Users/azimsaibou/Desktop/php projects/sous-controle-docker/www/sous_controle/vendor/pestphp/pest/src/Concerns/Testable.php(419): call_user_func_array(Object(Closure), Array)
#3 /Users/azimsaibou/Desktop/php projects/sous-controle-docker/www/sous_controle/vendor/pestphp/pest/src/Support/ExceptionTrace.php(26): P\Tests\Unit\ExceptionHandlerTest->{closure:Pest\Concerns\Testable::__callClosure():419}()
#4 /Users/azimsaibou/Desktop/php projects/sous-controle-docker/www/sous_controle/vendor/pestphp/pest/src/Concerns/Testable.php(419): Pest\Support\ExceptionTrace::ensure(Object(Closure))
#5 /Users/azimsaibou/Desktop/php projects/sous-controle-docker/www/sous_controle/vendor/pestphp/pest/src/Concerns/Testable.php(321): P\Tests\Unit\ExceptionHandlerTest->__callClosure(Object(Closure), Array)
#6 /Users/azimsaibou/Desktop/php projects/sous-controle-docker/www/sous_controle/vendor/pestphp/pest/src/Factories/TestCaseFactory.php(169) : eval()'d code(35): P\Tests\Unit\ExceptionHandlerTest->__runTest(Object(Closure))
#7 /Users/azimsaibou/Desktop/php projects/sous-controle-docker/www/sous_controle/vendor/phpunit/phpunit/src/Framework/TestCase.php(1235): P\Tests\Unit\ExceptionHandlerTest->__pest_evaluable_it_print_a_generic_message_in_production_mode_when_a_page_not_found_exception_is_thrown()
#8 /Users/azimsaibou/Desktop/php projects/sous-controle-docker/www/sous_controle/vendor/phpunit/phpunit/src/Framework/TestCase.php(514): PHPUnit\Framework\TestCase->runTest()
#9 /Users/azimsaibou/Desktop/php projects/sous-controle-docker/www/sous_controle/vendor/phpunit/phpunit/src/Framework/TestRunner/TestRunner.php(87): PHPUnit\Framework\TestCase->runBare()
#10 /Users/azimsaibou/Desktop/php projects/sous-controle-docker/www/sous_controle/vendor/phpunit/phpunit/src/Framework/TestCase.php(361): PHPUnit\Framework\TestRunner->run(Object(P\Tests\Unit\ExceptionHandlerTest))
#11 /Users/azimsaibou/Desktop/php projects/sous-controle-docker/www/sous_controle/vendor/phpunit/phpunit/src/Framework/TestSuite.php(369): PHPUnit\Framework\TestCase->run()
#12 /Users/azimsaibou/Desktop/php projects/sous-controle-docker/www/sous_controle/vendor/phpunit/phpunit/src/Framework/TestSuite.php(369): PHPUnit\Framework\TestSuite->run()
#13 /Users/azimsaibou/Desktop/php projects/sous-controle-docker/www/sous_controle/vendor/phpunit/phpunit/src/Framework/TestSuite.php(369): PHPUnit\Framework\TestSuite->run()
#14 /Users/azimsaibou/Desktop/php projects/sous-controle-docker/www/sous_controle/vendor/phpunit/phpunit/src/TextUI/TestRunner.php(64): PHPUnit\Framework\TestSuite->run()
#15 /Users/azimsaibou/Desktop/php projects/sous-controle-docker/www/sous_controle/vendor/phpunit/phpunit/src/TextUI/Application.php(210): PHPUnit\TextUI\TestRunner->run(Object(PHPUnit\TextUI\Configuration\Configuration), Object(PHPUnit\Runner\ResultCache\DefaultResultCache), Object(PHPUnit\Framework\TestSuite))
#16 /Users/azimsaibou/Desktop/php projects/sous-controle-docker/www/sous_controle/vendor/pestphp/pest/src/Kernel.php(103): PHPUnit\TextUI\Application->run(Array)
#17 /Users/azimsaibou/Desktop/php projects/sous-controle-docker/www/sous_controle/vendor/pestphp/pest/bin/pest(184): Pest\Kernel->handle(Array, Array)
#18 /Users/azimsaibou/Desktop/php projects/sous-controle-docker/www/sous_controle/vendor/pestphp/pest/bin/pest(192): {closure:/Users/azimsaibou/Desktop/php projects/sous-controle-docker/www/sous_controle/vendor/pestphp/pest/bin/pest:18}()
#19 /Users/azimsaibou/Desktop/php projects/sous-controle-docker/www/sous_controle/vendor/bin/pest(119): include('/Users/azimsaib...')
#20 {main}

[2025-03-28 23:05:44] Exception: A Page Is Not Found 
in /Users/azimsaibou/Desktop/php projects/sous-controle-docker/www/sous_controle/tests/Unit/ExceptionHandlerTest.php 
on line 63
Trace: #0 /Users/azimsaibou/Desktop/php projects/sous-controle-docker/www/sous_controle/vendor/pestphp/pest/src/Factories/TestCaseMethodFactory.php(168): P\Tests\Unit\ExceptionHandlerTest->{closure:/Users/azimsaibou/Desktop/php projects/sous-controle-docker/www/sous_controle/tests/Unit/ExceptionHandlerTest.php:55}()
#1 [internal function]: P\Tests\Unit\ExceptionHandlerTest->{closure:Pest\Factories\TestCaseMethodFactory::getClosure():158}()
#2 /Users/azimsaibou/Desktop/php projects/sous-controle-docker/www/sous_controle/vendor/pestphp/pest/src/Concerns/Testable.php(419): call_user_func_array(Object(Closure), Array)
#3 /Users/azimsaibou/Desktop/php projects/sous-controle-docker/www/sous_controle/vendor/pestphp/pest/src/Support/ExceptionTrace.php(26): P\Tests\Unit\ExceptionHandlerTest->{closure:Pest\Concerns\Testable::__callClosure():419}()
#4 /Users/azimsaibou/Desktop/php projects/sous-controle-docker/www/sous_controle/vendor/pestphp/pest/src/Concerns/Testable.php(419): Pest\Support\ExceptionTrace::ensure(Object(Closure))
#5 /Users/azimsaibou/Desktop/php projects/sous-controle-docker/www/sous_controle/vendor/pestphp/pest/src/Concerns/Testable.php(321): P\Tests\Unit\ExceptionHandlerTest->__callClosure(Object(Closure), Array)
#6 /Users/azimsaibou/Desktop/php projects/sous-controle-docker/www/sous_controle/vendor/pestphp/pest/src/Factories/TestCaseFactory.php(169) : eval()'d code(44): P\Tests\Unit\ExceptionHandlerTest->__runTest(Object(Closure))
#7 /Users/azimsaibou/Desktop/php projects/sous-controle-docker/www/sous_controle/vendor/phpunit/phpunit/src/Framework/TestCase.php(1235): P\Tests\Unit\ExceptionHandlerTest->__pest_evaluable_it_print_a_generic_message_in_production_mode_when_other_exception_is_thrown()
#8 /Users/azimsaibou/Desktop/php projects/sous-controle-docker/www/sous_controle/vendor/phpunit/phpunit/src/Framework/TestCase.php(514): PHPUnit\Framework\TestCase->runTest()
#9 /Users/azimsaibou/Desktop/php projects/sous-controle-docker/www/sous_controle/vendor/phpunit/phpunit/src/Framework/TestRunner/TestRunner.php(87): PHPUnit\Framework\TestCase->runBare()
#10 /Users/azimsaibou/Desktop/php projects/sous-controle-docker/www/sous_controle/vendor/phpunit/phpunit/src/Framework/TestCase.php(361): PHPUnit\Framework\TestRunner->run(Object(P\Tests\Unit\ExceptionHandlerTest))
#11 /Users/azimsaibou/Desktop/php projects/sous-controle-docker/www/sous_controle/vendor/phpunit/phpunit/src/Framework/TestSuite.php(369): PHPUnit\Framework\TestCase->run()
#12 /Users/azimsaibou/Desktop/php projects/sous-controle-docker/www/sous_controle/vendor/phpunit/phpunit/src/Framework/TestSuite.php(369): PHPUnit\Framework\TestSuite->run()
#13 /Users/azimsaibou/Desktop/php projects/sous-controle-docker/www/sous_controle/vendor/phpunit/phpunit/src/Framework/TestSuite.php(369): PHPUnit\Framework\TestSuite->run()
#14 /Users/azimsaibou/Desktop/php projects/sous-controle-docker/www/sous_controle/vendor/phpunit/phpunit/src/TextUI/TestRunner.php(64): PHPUnit\Framework\TestSuite->run()
#15 /Users/azimsaibou/Desktop/php projects/sous-controle-docker/www/sous_controle/vendor/phpunit/phpunit/src/TextUI/Application.php(210): PHPUnit\TextUI\TestRunner->run(Object(PHPUnit\TextUI\Configuration\Configuration), Object(PHPUnit\Runner\ResultCache\DefaultResultCache), Object(PHPUnit\Framework\TestSuite))
#16 /Users/azimsaibou/Desktop/php projects/sous-controle-docker/www/sous_controle/vendor/pestphp/pest/src/Kernel.php(103): PHPUnit\TextUI\Application->run(Array)
#17 /Users/azimsaibou/Desktop/php projects/sous-controle-docker/www/sous_controle/vendor/pestphp/pest/bin/pest(184): Pest\Kernel->handle(Array, Array)
#18 /Users/azimsaibou/Desktop/php projects/sous-controle-docker/www/sous_controle/vendor/pestphp/pest/bin/pest(192): {closure:/Users/azimsaibou/Desktop/php projects/sous-controle-docker/www/sous_controle/vendor/pestphp/pest/bin/pest:18}()
#19 /Users/azimsaibou/Desktop/php projects/sous-controle-docker/www/sous_controle/vendor/bin/pest(119): include('/Users/azimsaib...')
#20 {main}

[2025-03-28 23:06:18] Exception: A Page Is Not Found 
in /Users/azimsaibou/Desktop/php projects/sous-controle-docker/www/sous_controle/tests/Unit/ExceptionHandlerTest.php 
on line 49
Trace: #0 /Users/azimsaibou/Desktop/php projects/sous-controle-docker/www/sous_controle/vendor/pestphp/pest/src/Factories/TestCaseMethodFactory.php(168): P\Tests\Unit\ExceptionHandlerTest->{closure:/Users/azimsaibou/Desktop/php projects/sous-controle-docker/www/sous_controle/tests/Unit/ExceptionHandlerTest.php:42}()
#1 [internal function]: P\Tests\Unit\ExceptionHandlerTest->{closure:Pest\Factories\TestCaseMethodFactory::getClosure():158}()
#2 /Users/azimsaibou/Desktop/php projects/sous-controle-docker/www/sous_controle/vendor/pestphp/pest/src/Concerns/Testable.php(419): call_user_func_array(Object(Closure), Array)
#3 /Users/azimsaibou/Desktop/php projects/sous-controle-docker/www/sous_controle/vendor/pestphp/pest/src/Support/ExceptionTrace.php(26): P\Tests\Unit\ExceptionHandlerTest->{closure:Pest\Concerns\Testable::__callClosure():419}()
#4 /Users/azimsaibou/Desktop/php projects/sous-controle-docker/www/sous_controle/vendor/pestphp/pest/src/Concerns/Testable.php(419): Pest\Support\ExceptionTrace::ensure(Object(Closure))
#5 /Users/azimsaibou/Desktop/php projects/sous-controle-docker/www/sous_controle/vendor/pestphp/pest/src/Concerns/Testable.php(321): P\Tests\Unit\ExceptionHandlerTest->__callClosure(Object(Closure), Array)
#6 /Users/azimsaibou/Desktop/php projects/sous-controle-docker/www/sous_controle/vendor/pestphp/pest/src/Factories/TestCaseFactory.php(169) : eval()'d code(35): P\Tests\Unit\ExceptionHandlerTest->__runTest(Object(Closure))
#7 /Users/azimsaibou/Desktop/php projects/sous-controle-docker/www/sous_controle/vendor/phpunit/phpunit/src/Framework/TestCase.php(1235): P\Tests\Unit\ExceptionHandlerTest->__pest_evaluable_it_print_a_generic_message_in_production_mode_when_a_page_not_found_exception_is_thrown()
#8 /Users/azimsaibou/Desktop/php projects/sous-controle-docker/www/sous_controle/vendor/phpunit/phpunit/src/Framework/TestCase.php(514): PHPUnit\Framework\TestCase->runTest()
#9 /Users/azimsaibou/Desktop/php projects/sous-controle-docker/www/sous_controle/vendor/phpunit/phpunit/src/Framework/TestRunner/TestRunner.php(87): PHPUnit\Framework\TestCase->runBare()
#10 /Users/azimsaibou/Desktop/php projects/sous-controle-docker/www/sous_controle/vendor/phpunit/phpunit/src/Framework/TestCase.php(361): PHPUnit\Framework\TestRunner->run(Object(P\Tests\Unit\ExceptionHandlerTest))
#11 /Users/azimsaibou/Desktop/php projects/sous-controle-docker/www/sous_controle/vendor/phpunit/phpunit/src/Framework/TestSuite.php(369): PHPUnit\Framework\TestCase->run()
#12 /Users/azimsaibou/Desktop/php projects/sous-controle-docker/www/sous_controle/vendor/phpunit/phpunit/src/Framework/TestSuite.php(369): PHPUnit\Framework\TestSuite->run()
#13 /Users/azimsaibou/Desktop/php projects/sous-controle-docker/www/sous_controle/vendor/phpunit/phpunit/src/Framework/TestSuite.php(369): PHPUnit\Framework\TestSuite->run()
#14 /Users/azimsaibou/Desktop/php projects/sous-controle-docker/www/sous_controle/vendor/phpunit/phpunit/src/TextUI/TestRunner.php(64): PHPUnit\Framework\TestSuite->run()
#15 /Users/azimsaibou/Desktop/php projects/sous-controle-docker/www/sous_controle/vendor/phpunit/phpunit/src/TextUI/Application.php(210): PHPUnit\TextUI\TestRunner->run(Object(PHPUnit\TextUI\Configuration\Configuration), Object(PHPUnit\Runner\ResultCache\DefaultResultCache), Object(PHPUnit\Framework\TestSuite))
#16 /Users/azimsaibou/Desktop/php projects/sous-controle-docker/www/sous_controle/vendor/pestphp/pest/src/Kernel.php(103): PHPUnit\TextUI\Application->run(Array)
#17 /Users/azimsaibou/Desktop/php projects/sous-controle-docker/www/sous_controle/vendor/pestphp/pest/bin/pest(184): Pest\Kernel->handle(Array, Array)
#18 /Users/azimsaibou/Desktop/php projects/sous-controle-docker/www/sous_controle/vendor/pestphp/pest/bin/pest(192): {closure:/Users/azimsaibou/Desktop/php projects/sous-controle-docker/www/sous_controle/vendor/pestphp/pest/bin/pest:18}()
#19 /Users/azimsaibou/Desktop/php projects/sous-controle-docker/www/sous_controle/vendor/bin/pest(119): include('/Users/azimsaib...')
#20 {main}

[2025-03-28 23:06:18] Exception: A Page Is Not Found 
in /Users/azimsaibou/Desktop/php projects/sous-controle-docker/www/sous_controle/tests/Unit/ExceptionHandlerTest.php 
on line 63
Trace: #0 /Users/azimsaibou/Desktop/php projects/sous-controle-docker/www/sous_controle/vendor/pestphp/pest/src/Factories/TestCaseMethodFactory.php(168): P\Tests\Unit\ExceptionHandlerTest->{closure:/Users/azimsaibou/Desktop/php projects/sous-controle-docker/www/sous_controle/tests/Unit/ExceptionHandlerTest.php:55}()
#1 [internal function]: P\Tests\Unit\ExceptionHandlerTest->{closure:Pest\Factories\TestCaseMethodFactory::getClosure():158}()
#2 /Users/azimsaibou/Desktop/php projects/sous-controle-docker/www/sous_controle/vendor/pestphp/pest/src/Concerns/Testable.php(419): call_user_func_array(Object(Closure), Array)
#3 /Users/azimsaibou/Desktop/php projects/sous-controle-docker/www/sous_controle/vendor/pestphp/pest/src/Support/ExceptionTrace.php(26): P\Tests\Unit\ExceptionHandlerTest->{closure:Pest\Concerns\Testable::__callClosure():419}()
#4 /Users/azimsaibou/Desktop/php projects/sous-controle-docker/www/sous_controle/vendor/pestphp/pest/src/Concerns/Testable.php(419): Pest\Support\ExceptionTrace::ensure(Object(Closure))
#5 /Users/azimsaibou/Desktop/php projects/sous-controle-docker/www/sous_controle/vendor/pestphp/pest/src/Concerns/Testable.php(321): P\Tests\Unit\ExceptionHandlerTest->__callClosure(Object(Closure), Array)
#6 /Users/azimsaibou/Desktop/php projects/sous-controle-docker/www/sous_controle/vendor/pestphp/pest/src/Factories/TestCaseFactory.php(169) : eval()'d code(44): P\Tests\Unit\ExceptionHandlerTest->__runTest(Object(Closure))
#7 /Users/azimsaibou/Desktop/php projects/sous-controle-docker/www/sous_controle/vendor/phpunit/phpunit/src/Framework/TestCase.php(1235): P\Tests\Unit\ExceptionHandlerTest->__pest_evaluable_it_print_a_generic_message_in_production_mode_when_other_exception_is_thrown()
#8 /Users/azimsaibou/Desktop/php projects/sous-controle-docker/www/sous_controle/vendor/phpunit/phpunit/src/Framework/TestCase.php(514): PHPUnit\Framework\TestCase->runTest()
#9 /Users/azimsaibou/Desktop/php projects/sous-controle-docker/www/sous_controle/vendor/phpunit/phpunit/src/Framework/TestRunner/TestRunner.php(87): PHPUnit\Framework\TestCase->runBare()
#10 /Users/azimsaibou/Desktop/php projects/sous-controle-docker/www/sous_controle/vendor/phpunit/phpunit/src/Framework/TestCase.php(361): PHPUnit\Framework\TestRunner->run(Object(P\Tests\Unit\ExceptionHandlerTest))
#11 /Users/azimsaibou/Desktop/php projects/sous-controle-docker/www/sous_controle/vendor/phpunit/phpunit/src/Framework/TestSuite.php(369): PHPUnit\Framework\TestCase->run()
#12 /Users/azimsaibou/Desktop/php projects/sous-controle-docker/www/sous_controle/vendor/phpunit/phpunit/src/Framework/TestSuite.php(369): PHPUnit\Framework\TestSuite->run()
#13 /Users/azimsaibou/Desktop/php projects/sous-controle-docker/www/sous_controle/vendor/phpunit/phpunit/src/Framework/TestSuite.php(369): PHPUnit\Framework\TestSuite->run()
#14 /Users/azimsaibou/Desktop/php projects/sous-controle-docker/www/sous_controle/vendor/phpunit/phpunit/src/TextUI/TestRunner.php(64): PHPUnit\Framework\TestSuite->run()
#15 /Users/azimsaibou/Desktop/php projects/sous-controle-docker/www/sous_controle/vendor/phpunit/phpunit/src/TextUI/Application.php(210): PHPUnit\TextUI\TestRunner->run(Object(PHPUnit\TextUI\Configuration\Configuration), Object(PHPUnit\Runner\ResultCache\DefaultResultCache), Object(PHPUnit\Framework\TestSuite))
#16 /Users/azimsaibou/Desktop/php projects/sous-controle-docker/www/sous_controle/vendor/pestphp/pest/src/Kernel.php(103): PHPUnit\TextUI\Application->run(Array)
#17 /Users/azimsaibou/Desktop/php projects/sous-controle-docker/www/sous_controle/vendor/pestphp/pest/bin/pest(184): Pest\Kernel->handle(Array, Array)
#18 /Users/azimsaibou/Desktop/php projects/sous-controle-docker/www/sous_controle/vendor/pestphp/pest/bin/pest(192): {closure:/Users/azimsaibou/Desktop/php projects/sous-controle-docker/www/sous_controle/vendor/pestphp/pest/bin/pest:18}()
#19 /Users/azimsaibou/Desktop/php projects/sous-controle-docker/www/sous_controle/vendor/bin/pest(119): include('/Users/azimsaib...')
#20 {main}

[2025-03-28 23:06:47] Exception: A Page Is Not Found 
in /Users/azimsaibou/Desktop/php projects/sous-controle-docker/www/sous_controle/tests/Unit/ExceptionHandlerTest.php 
on line 49
Trace: #0 /Users/azimsaibou/Desktop/php projects/sous-controle-docker/www/sous_controle/vendor/pestphp/pest/src/Factories/TestCaseMethodFactory.php(168): P\Tests\Unit\ExceptionHandlerTest->{closure:/Users/azimsaibou/Desktop/php projects/sous-controle-docker/www/sous_controle/tests/Unit/ExceptionHandlerTest.php:42}()
#1 [internal function]: P\Tests\Unit\ExceptionHandlerTest->{closure:Pest\Factories\TestCaseMethodFactory::getClosure():158}()
#2 /Users/azimsaibou/Desktop/php projects/sous-controle-docker/www/sous_controle/vendor/pestphp/pest/src/Concerns/Testable.php(419): call_user_func_array(Object(Closure), Array)
#3 /Users/azimsaibou/Desktop/php projects/sous-controle-docker/www/sous_controle/vendor/pestphp/pest/src/Support/ExceptionTrace.php(26): P\Tests\Unit\ExceptionHandlerTest->{closure:Pest\Concerns\Testable::__callClosure():419}()
#4 /Users/azimsaibou/Desktop/php projects/sous-controle-docker/www/sous_controle/vendor/pestphp/pest/src/Concerns/Testable.php(419): Pest\Support\ExceptionTrace::ensure(Object(Closure))
#5 /Users/azimsaibou/Desktop/php projects/sous-controle-docker/www/sous_controle/vendor/pestphp/pest/src/Concerns/Testable.php(321): P\Tests\Unit\ExceptionHandlerTest->__callClosure(Object(Closure), Array)
#6 /Users/azimsaibou/Desktop/php projects/sous-controle-docker/www/sous_controle/vendor/pestphp/pest/src/Factories/TestCaseFactory.php(169) : eval()'d code(35): P\Tests\Unit\ExceptionHandlerTest->__runTest(Object(Closure))
#7 /Users/azimsaibou/Desktop/php projects/sous-controle-docker/www/sous_controle/vendor/phpunit/phpunit/src/Framework/TestCase.php(1235): P\Tests\Unit\ExceptionHandlerTest->__pest_evaluable_it_print_a_generic_message_in_production_mode_when_a_page_not_found_exception_is_thrown()
#8 /Users/azimsaibou/Desktop/php projects/sous-controle-docker/www/sous_controle/vendor/phpunit/phpunit/src/Framework/TestCase.php(514): PHPUnit\Framework\TestCase->runTest()
#9 /Users/azimsaibou/Desktop/php projects/sous-controle-docker/www/sous_controle/vendor/phpunit/phpunit/src/Framework/TestRunner/TestRunner.php(87): PHPUnit\Framework\TestCase->runBare()
#10 /Users/azimsaibou/Desktop/php projects/sous-controle-docker/www/sous_controle/vendor/phpunit/phpunit/src/Framework/TestCase.php(361): PHPUnit\Framework\TestRunner->run(Object(P\Tests\Unit\ExceptionHandlerTest))
#11 /Users/azimsaibou/Desktop/php projects/sous-controle-docker/www/sous_controle/vendor/phpunit/phpunit/src/Framework/TestSuite.php(369): PHPUnit\Framework\TestCase->run()
#12 /Users/azimsaibou/Desktop/php projects/sous-controle-docker/www/sous_controle/vendor/phpunit/phpunit/src/Framework/TestSuite.php(369): PHPUnit\Framework\TestSuite->run()
#13 /Users/azimsaibou/Desktop/php projects/sous-controle-docker/www/sous_controle/vendor/phpunit/phpunit/src/Framework/TestSuite.php(369): PHPUnit\Framework\TestSuite->run()
#14 /Users/azimsaibou/Desktop/php projects/sous-controle-docker/www/sous_controle/vendor/phpunit/phpunit/src/TextUI/TestRunner.php(64): PHPUnit\Framework\TestSuite->run()
#15 /Users/azimsaibou/Desktop/php projects/sous-controle-docker/www/sous_controle/vendor/phpunit/phpunit/src/TextUI/Application.php(210): PHPUnit\TextUI\TestRunner->run(Object(PHPUnit\TextUI\Configuration\Configuration), Object(PHPUnit\Runner\ResultCache\DefaultResultCache), Object(PHPUnit\Framework\TestSuite))
#16 /Users/azimsaibou/Desktop/php projects/sous-controle-docker/www/sous_controle/vendor/pestphp/pest/src/Kernel.php(103): PHPUnit\TextUI\Application->run(Array)
#17 /Users/azimsaibou/Desktop/php projects/sous-controle-docker/www/sous_controle/vendor/pestphp/pest/bin/pest(184): Pest\Kernel->handle(Array, Array)
#18 /Users/azimsaibou/Desktop/php projects/sous-controle-docker/www/sous_controle/vendor/pestphp/pest/bin/pest(192): {closure:/Users/azimsaibou/Desktop/php projects/sous-controle-docker/www/sous_controle/vendor/pestphp/pest/bin/pest:18}()
#19 /Users/azimsaibou/Desktop/php projects/sous-controle-docker/www/sous_controle/vendor/bin/pest(119): include('/Users/azimsaib...')
#20 {main}

[2025-03-28 23:06:47] Exception: A Page Is Not Found 
in /Users/azimsaibou/Desktop/php projects/sous-controle-docker/www/sous_controle/tests/Unit/ExceptionHandlerTest.php 
on line 63
Trace: #0 /Users/azimsaibou/Desktop/php projects/sous-controle-docker/www/sous_controle/vendor/pestphp/pest/src/Factories/TestCaseMethodFactory.php(168): P\Tests\Unit\ExceptionHandlerTest->{closure:/Users/azimsaibou/Desktop/php projects/sous-controle-docker/www/sous_controle/tests/Unit/ExceptionHandlerTest.php:55}()
#1 [internal function]: P\Tests\Unit\ExceptionHandlerTest->{closure:Pest\Factories\TestCaseMethodFactory::getClosure():158}()
#2 /Users/azimsaibou/Desktop/php projects/sous-controle-docker/www/sous_controle/vendor/pestphp/pest/src/Concerns/Testable.php(419): call_user_func_array(Object(Closure), Array)
#3 /Users/azimsaibou/Desktop/php projects/sous-controle-docker/www/sous_controle/vendor/pestphp/pest/src/Support/ExceptionTrace.php(26): P\Tests\Unit\ExceptionHandlerTest->{closure:Pest\Concerns\Testable::__callClosure():419}()
#4 /Users/azimsaibou/Desktop/php projects/sous-controle-docker/www/sous_controle/vendor/pestphp/pest/src/Concerns/Testable.php(419): Pest\Support\ExceptionTrace::ensure(Object(Closure))
#5 /Users/azimsaibou/Desktop/php projects/sous-controle-docker/www/sous_controle/vendor/pestphp/pest/src/Concerns/Testable.php(321): P\Tests\Unit\ExceptionHandlerTest->__callClosure(Object(Closure), Array)
#6 /Users/azimsaibou/Desktop/php projects/sous-controle-docker/www/sous_controle/vendor/pestphp/pest/src/Factories/TestCaseFactory.php(169) : eval()'d code(44): P\Tests\Unit\ExceptionHandlerTest->__runTest(Object(Closure))
#7 /Users/azimsaibou/Desktop/php projects/sous-controle-docker/www/sous_controle/vendor/phpunit/phpunit/src/Framework/TestCase.php(1235): P\Tests\Unit\ExceptionHandlerTest->__pest_evaluable_it_print_a_generic_message_in_production_mode_when_other_exception_is_thrown()
#8 /Users/azimsaibou/Desktop/php projects/sous-controle-docker/www/sous_controle/vendor/phpunit/phpunit/src/Framework/TestCase.php(514): PHPUnit\Framework\TestCase->runTest()
#9 /Users/azimsaibou/Desktop/php projects/sous-controle-docker/www/sous_controle/vendor/phpunit/phpunit/src/Framework/TestRunner/TestRunner.php(87): PHPUnit\Framework\TestCase->runBare()
#10 /Users/azimsaibou/Desktop/php projects/sous-controle-docker/www/sous_controle/vendor/phpunit/phpunit/src/Framework/TestCase.php(361): PHPUnit\Framework\TestRunner->run(Object(P\Tests\Unit\ExceptionHandlerTest))
#11 /Users/azimsaibou/Desktop/php projects/sous-controle-docker/www/sous_controle/vendor/phpunit/phpunit/src/Framework/TestSuite.php(369): PHPUnit\Framework\TestCase->run()
#12 /Users/azimsaibou/Desktop/php projects/sous-controle-docker/www/sous_controle/vendor/phpunit/phpunit/src/Framework/TestSuite.php(369): PHPUnit\Framework\TestSuite->run()
#13 /Users/azimsaibou/Desktop/php projects/sous-controle-docker/www/sous_controle/vendor/phpunit/phpunit/src/Framework/TestSuite.php(369): PHPUnit\Framework\TestSuite->run()
#14 /Users/azimsaibou/Desktop/php projects/sous-controle-docker/www/sous_controle/vendor/phpunit/phpunit/src/TextUI/TestRunner.php(64): PHPUnit\Framework\TestSuite->run()
#15 /Users/azimsaibou/Desktop/php projects/sous-controle-docker/www/sous_controle/vendor/phpunit/phpunit/src/TextUI/Application.php(210): PHPUnit\TextUI\TestRunner->run(Object(PHPUnit\TextUI\Configuration\Configuration), Object(PHPUnit\Runner\ResultCache\DefaultResultCache), Object(PHPUnit\Framework\TestSuite))
#16 /Users/azimsaibou/Desktop/php projects/sous-controle-docker/www/sous_controle/vendor/pestphp/pest/src/Kernel.php(103): PHPUnit\TextUI\Application->run(Array)
#17 /Users/azimsaibou/Desktop/php projects/sous-controle-docker/www/sous_controle/vendor/pestphp/pest/bin/pest(184): Pest\Kernel->handle(Array, Array)
#18 /Users/azimsaibou/Desktop/php projects/sous-controle-docker/www/sous_controle/vendor/pestphp/pest/bin/pest(192): {closure:/Users/azimsaibou/Desktop/php projects/sous-controle-docker/www/sous_controle/vendor/pestphp/pest/bin/pest:18}()
#19 /Users/azimsaibou/Desktop/php projects/sous-controle-docker/www/sous_controle/vendor/bin/pest(119): include('/Users/azimsaib...')
#20 {main}

